Workbook

Sheet 📊 Dashboard
A1: 🏛️ GST NOTICE TRACKER - IMPRESSIONS SERVICES PVT LTD
A2: 📍 19 State/UT Registrations | Section 73 & 74 Cases | DGGI Matters
A3: 📅 Last Updated: | B3: =NOW() -> 46221.297
A5: 📊 KEY METRICS SUMMARY
A6: 📋 Total Cases | C6: ⏳ Pending Cases | E6: ✅ Completed | G6: 📝 Reply Pending | L6: ⚖️ Under Appeal
A7: =COUNTA('📋 All Notices'!A:A)-1 -> 34 | C7: =COUNTIF('📋 All Notices'!Q:Q,"Active")+COUNTIF('📋 All Notices'!R:R,"Pending*") -> 31 | E7: =COUNTIF('📋 All Notices'!Q:Q,"Completed")+COUNTIF('📋 All Notices'!Q:Q,"Closed")+COUNTIF('📋 All Notices'!Q:Q,"Dropped") -> 3 | G7: =COUNTIF('📋 All Notices'!Q:Q,"Pending Reply") -> 0 | L7: =COUNTIF('📋 All Notices'!R:R,"Appeal Filed") -> 0
A9: 💰 TAX DEMAND SUMMARY (₹)
A10: Total Demand | C10: IGST Demand | E10: CGST Demand | G10: SGST Demand | I10: Interest Demand | J10: Penalty Demand | K10: Late fee Demand | L10: Appeal Deposited
A11: =SUM('📋 All Notices'!O:O) -> 6.2590598e+08 | C11: =SUM('📋 All Notices'!I:I) -> 125614709 | E11: =SUM('📋 All Notices'!J:J) -> 87718454 | G11: =SUM('📋 All Notices'!K:K) -> 87718333 | I11: =SUMIF('📋 All Notices'!$A$3:$A1006,">0",'📋 All Notices'!L$3:L1006) -> 99631053 | J11: =SUMIF('📋 All Notices'!$A$3:$A1006,">0",'📋 All Notices'!M$3:M1006) -> 2.2357119e+08 | K11: =SUMIF('📋 All Notices'!$A$3:$A1006,">0",'📋 All Notices'!N$3:N1006) -> 1652240 | L11: =SUM('📋 All Notices'!P:P) -> 6030483
A13: 📑 CASE TYPE SUMMARY | F13: 📍 STATE-WISE SUMMARY
A14: Case Type | B14: Total | C14: Pending | D14: Demand (₹) | F14: State | G14: Cases | H14: Pending | L14: Demand (₹) | M14: Completed
A15: Sec 74 - DGGI | B15: =COUNTIF('📋 All Notices'!E:E,"*74*DGGI*") -> 14 | C15: =COUNTIFS('📋 All Notices'!E:E,"*74*DGGI*",'📋 All Notices'!Q:Q,"<>Completed",'📋 All Notices'!Q:Q,"<>Closed",'📋 All Notices'!Q:Q,"<>Dropped") -> 14 | D15: =SUMIF('📋 All Notices'!E:E,"*74*DGGI*",'📋 All Notices'!O:O) -> 366872521 | F15: Andhra Pradesh | G15: =COUNTIF('📋 All Notices'!B:B,"*Andhra Pradesh*") -> 0 | H15: =COUNTIFS('📋 All Notices'!B:B,"*Andhra Pradesh*",'📋 All Notices'!Q:Q,"<>Completed",'📋 All Notices'!Q:Q,"<>Closed",'📋 All Notices'!Q:Q,"<>Dropped") -> 0 | L15: =SUMIF('📋 All Notices'!B:B,"*Andhra Pradesh*",'📋 All Notices'!O:O) -> 0 | M15: =COUNTIFS('📋 All Notices'!B:B,"*Andhra Pradesh*",'📋 All Notices'!Q:Q,"Completed")+COUNTIFS('📋 All Notices'!B:B,"*Andhra Pradesh*",'📋 All Notices'!Q:Q,"Closed") -> 0
A16: Sec 74 - Other | B16: =COUNTIF('📋 All Notices'!E:E,"*74*") -> 17 | C16: =COUNTIFS('📋 All Notices'!E:E,"*74*",'📋 All Notices'!Q:Q,"<>Completed",'📋 All Notices'!Q:Q,"<>Closed",'📋 All Notices'!Q:Q,"<>Dropped") -> 16 | D16: =SUMIF('📋 All Notices'!E:E,"DRC-01 (Sec 74)",'📋 All Notices'!O:O) -> 13398 | F16: Assam | G16: =COUNTIF('📋 All Notices'!B:B,"*Assam*") -> 0 | H16: =COUNTIFS('📋 All Notices'!B:B,"*Assam*",'📋 All Notices'!Q:Q,"<>Completed",'📋 All Notices'!Q:Q,"<>Closed",'📋 All Notices'!Q:Q,"<>Dropped") -> 0 | L16: =SUMIF('📋 All Notices'!B:B,"*Assam*",'📋 All Notices'!O:O) -> 0 | M16: =COUNTIFS('📋 All Notices'!B:B,"*Assam*",'📋 All Notices'!Q:Q,"Completed")+COUNTIFS('📋 All Notices'!B:B,"*Assam*",'📋 All Notices'!Q:Q,"Closed") -> 0
A17: Sec 73 | B17: =COUNTIF('📋 All Notices'!E:E,"*74*") -> 17 | C17: 1 | D17: =SUMIF('📋 All Notices'!E:E,"DRC-01 (Sec 73)",'📋 All Notices'!O:O) -> 7402773 | F17: Bihar | G17: =COUNTIF('📋 All Notices'!B:B,"*Bihar*") -> 0 | H17: =COUNTIFS('📋 All Notices'!B:B,"*Bihar*",'📋 All Notices'!Q:Q,"<>Completed",'📋 All Notices'!Q:Q,"<>Closed",'📋 All Notices'!Q:Q,"<>Dropped") -> 0 | L17: =SUMIF('📋 All Notices'!B:B,"*Bihar*",'📋 All Notices'!O:O) -> 0 | M17: =COUNTIFS('📋 All Notices'!B:B,"*Bihar*",'📋 All Notices'!Q:Q,"Completed")+COUNTIFS('📋 All Notices'!B:B,"*Bihar*",'📋 All Notices'!Q:Q,"Closed") -> 0
A18: DRC-01A | B18: =COUNTIF('📋 All Notices'!E:E,"*DRC-01A*") -> 0 | C18: =COUNTIFS('📋 All Notices'!E:E,"*DRC-01A*",'📋 All Notices'!Q:Q,"<>Completed",'📋 All Notices'!Q:Q,"<>Closed",'📋 All Notices'!Q:Q,"<>Dropped") -> 0 | D18: =SUMIF('📋 All Notices'!E:E,"*DRC-01A*",'📋 All Notices'!O:O) -> 0 | F18: Chandigarh | G18: =COUNTIF('📋 All Notices'!B:B,"*Chandigarh*") -> 0 | H18: =COUNTIFS('📋 All Notices'!B:B,"*Chandigarh*",'📋 All Notices'!Q:Q,"<>Completed",'📋 All Notices'!Q:Q,"<>Closed",'📋 All Notices'!Q:Q,"<>Dropped") -> 0 | L18: =SUMIF('📋 All Notices'!B:B,"*Chandigarh*",'📋 All Notices'!O:O) -> 0 | M18: =COUNTIFS('📋 All Notices'!B:B,"*Chandigarh*",'📋 All Notices'!Q:Q,"Completed")+COUNTIFS('📋 All Notices'!B:B,"*Chandigarh*",'📋 All Notices'!Q:Q,"Closed") -> 0
A19: DRC-07 | B19: =COUNTIF('📋 All Notices'!E:E,"*DRC-07 (Sec 73)*") -> 1 | C19: =COUNTIFS('📋 All Notices'!E:E,"*DRC-07*",'📋 All Notices'!Q:Q,"<>Completed",'📋 All Notices'!Q:Q,"<>Closed",'📋 All Notices'!Q:Q,"<>Dropped") -> 16 | D19: =SUMIF('📋 All Notices'!E:E,"DRC-07 (Sec 73)",'📋 All Notices'!O:O) -> 49276808 | F19: Delhi | G19: =COUNTIF('📋 All Notices'!B:B,"*Delhi*") -> 6 | H19: =COUNTIFS('📋 All Notices'!B:B,"*Delhi*",'📋 All Notices'!Q:Q,"<>Completed",'📋 All Notices'!Q:Q,"<>Closed",'📋 All Notices'!Q:Q,"<>Dropped") -> 5 | L19: =SUMIF('📋 All Notices'!B:B,"*Delhi*",'📋 All Notices'!O:O) -> 202985538 | M19: =COUNTIFS('📋 All Notices'!B:B,"*Delhi*",'📋 All Notices'!Q:Q,"Completed")+COUNTIFS('📋 All Notices'!B:B,"*Delhi*",'📋 All Notices'!Q:Q,"Closed") -> 1
A20: ASMT-10 | B20: =COUNTIF('📋 All Notices'!E:E,"*ASMT*") -> 2 | C20: =COUNTIFS('📋 All Notices'!E:E,"*ASMT*",'📋 All Notices'!Q:Q,"<>Completed",'📋 All Notices'!Q:Q,"<>Closed",'📋 All Notices'!Q:Q,"<>Dropped") -> 1 | D20: =SUMIF('📋 All Notices'!E:E,"*ASMT*",'📋 All Notices'!O:O) -> 8349118 | F20: Haryana | G20: =COUNTIF('📋 All Notices'!B:B,"*Haryana*") -> 11 | H20: =COUNTIFS('📋 All Notices'!B:B,"*Haryana*",'📋 All Notices'!Q:Q,"<>Completed",'📋 All Notices'!Q:Q,"<>Closed",'📋 All Notices'!Q:Q,"<>Dropped") -> 10 | L20: =SUMIF('📋 All Notices'!B:B,"*Haryana*",'📋 All Notices'!O:O) -> 2.8905357e+08 | M20: =COUNTIFS('📋 All Notices'!B:B,"*Haryana*",'📋 All Notices'!Q:Q,"Completed")+COUNTIFS('📋 All Notices'!B:B,"*Haryana*",'📋 All Notices'!Q:Q,"Closed") -> 1
A21: APL-01 (Appeal Filed) | B21: =COUNTIF('📋 All Notices'!E:E,"*APL-01 (Appeal Filed)*") -> 10 | C21: 6 | D21: =SUMIF('📋 All Notices'!E:E,"APL-01 (Appeal Filed)",'📋 All Notices'!O:O) -> 1.5242931e+08 | F21: Himachal Pradesh | G21: =COUNTIF('📋 All Notices'!B:B,"*Himachal Pradesh*") -> 1 | H21: =COUNTIFS('📋 All Notices'!B:B,"*Himachal Pradesh*",'📋 All Notices'!Q:Q,"<>Completed",'📋 All Notices'!Q:Q,"<>Closed",'📋 All Notices'!Q:Q,"<>Dropped") -> 1 | L21: =SUMIF('📋 All Notices'!B:B,"*Himachal Pradesh*",'📋 All Notices'!O:O) -> 121220 | M21: =COUNTIFS('📋 All Notices'!B:B,"*Himachal Pradesh*",'📋 All Notices'!Q:Q,"Completed")+COUNTIFS('📋 All Notices'!B:B,"*Himachal Pradesh*",'📋 All Notices'!Q:Q,"Closed") -> 0
F22: Jharkhand | G22: =COUNTIF('📋 All Notices'!B:B,"*Jharkhand*") -> 1 | H22: =COUNTIFS('📋 All Notices'!B:B,"*Jharkhand*",'📋 All Notices'!Q:Q,"<>Completed",'📋 All Notices'!Q:Q,"<>Closed",'📋 All Notices'!Q:Q,"<>Dropped") -> 1 | L22: =SUMIF('📋 All Notices'!B:B,"*Jharkhand*",'📋 All Notices'!O:O) -> 9816 | M22: =COUNTIFS('📋 All Notices'!B:B,"*Jharkhand*",'📋 All Notices'!Q:Q,"Completed")+COUNTIFS('📋 All Notices'!B:B,"*Jharkhand*",'📋 All Notices'!Q:Q,"Closed") -> 0
F23: Karnataka | G23: =COUNTIF('📋 All Notices'!B:B,"*Karnataka*") -> 1 | H23: =COUNTIFS('📋 All Notices'!B:B,"*Karnataka*",'📋 All Notices'!Q:Q,"<>Completed",'📋 All Notices'!Q:Q,"<>Closed",'📋 All Notices'!Q:Q,"<>Dropped") -> 1 | L23: =SUMIF('📋 All Notices'!B:B,"*Karnataka*",'📋 All Notices'!O:O) -> 264092 | M23: =COUNTIFS('📋 All Notices'!B:B,"*Karnataka*",'📋 All Notices'!Q:Q,"Completed")+COUNTIFS('📋 All Notices'!B:B,"*Karnataka*",'📋 All Notices'!Q:Q,"Closed") -> 0
F24: Kerala | G24: =COUNTIF('📋 All Notices'!B:B,"*Kerala*") -> 1 | H24: =COUNTIFS('📋 All Notices'!B:B,"*Kerala*",'📋 All Notices'!Q:Q,"<>Completed",'📋 All Notices'!Q:Q,"<>Closed",'📋 All Notices'!Q:Q,"<>Dropped") -> 1 | L24: =SUMIF('📋 All Notices'!B:B,"*Kerala*",'📋 All Notices'!O:O) -> 22702 | M24: =COUNTIFS('📋 All Notices'!B:B,"*Kerala*",'📋 All Notices'!Q:Q,"Completed")+COUNTIFS('📋 All Notices'!B:B,"*Kerala*",'📋 All Notices'!Q:Q,"Closed") -> 0
F25: Maharashtra | G25: =COUNTIF('📋 All Notices'!B:B,"*Maharashtra*") -> 3 | H25: =COUNTIFS('📋 All Notices'!B:B,"*Maharashtra*",'📋 All Notices'!Q:Q,"<>Completed",'📋 All Notices'!Q:Q,"<>Closed",'📋 All Notices'!Q:Q,"<>Dropped") -> 2 | L25: =SUMIF('📋 All Notices'!B:B,"*Maharashtra*",'📋 All Notices'!O:O) -> 34627402 | M25: =COUNTIFS('📋 All Notices'!B:B,"*Maharashtra*",'📋 All Notices'!Q:Q,"Completed")+COUNTIFS('📋 All Notices'!B:B,"*Maharashtra*",'📋 All Notices'!Q:Q,"Closed") -> 1
F26: Odisha | G26: =COUNTIF('📋 All Notices'!B:B,"*Odisha*") -> 0 | H26: =COUNTIFS('📋 All Notices'!B:B,"*Odisha*",'📋 All Notices'!Q:Q,"<>Completed",'📋 All Notices'!Q:Q,"<>Closed",'📋 All Notices'!Q:Q,"<>Dropped") -> 0 | L26: =SUMIF('📋 All Notices'!B:B,"*Odisha*",'📋 All Notices'!O:O) -> 0 | M26: =COUNTIFS('📋 All Notices'!B:B,"*Odisha*",'📋 All Notices'!Q:Q,"Completed")+COUNTIFS('📋 All Notices'!B:B,"*Odisha*",'📋 All Notices'!Q:Q,"Closed") -> 0
F27: Punjab | G27: =COUNTIF('📋 All Notices'!B:B,"*Punjab*") -> 0 | H27: =COUNTIFS('📋 All Notices'!B:B,"*Punjab*",'📋 All Notices'!Q:Q,"<>Completed",'📋 All Notices'!Q:Q,"<>Closed",'📋 All Notices'!Q:Q,"<>Dropped") -> 0 | L27: =SUMIF('📋 All Notices'!B:B,"*Punjab*",'📋 All Notices'!O:O) -> 0 | M27: =COUNTIFS('📋 All Notices'!B:B,"*Punjab*",'📋 All Notices'!Q:Q,"Completed")+COUNTIFS('📋 All Notices'!B:B,"*Punjab*",'📋 All Notices'!Q:Q,"Closed") -> 0
F28: Rajasthan | G28: =COUNTIF('📋 All Notices'!B:B,"*Rajasthan*") -> 1 | H28: =COUNTIFS('📋 All Notices'!B:B,"*Rajasthan*",'📋 All Notices'!Q:Q,"<>Completed",'📋 All Notices'!Q:Q,"<>Closed",'📋 All Notices'!Q:Q,"<>Dropped") -> 1 | L28: =SUMIF('📋 All Notices'!B:B,"*Rajasthan*",'📋 All Notices'!O:O) -> 546060 | M28: =COUNTIFS('📋 All Notices'!B:B,"*Rajasthan*",'📋 All Notices'!Q:Q,"Completed")+COUNTIFS('📋 All Notices'!B:B,"*Rajasthan*",'📋 All Notices'!Q:Q,"Closed") -> 0
F29: Tamil Nadu | G29: =COUNTIF('📋 All Notices'!B:B,"*Tamil Nadu*") -> 0 | H29: =COUNTIFS('📋 All Notices'!B:B,"*Tamil Nadu*",'📋 All Notices'!Q:Q,"<>Completed",'📋 All Notices'!Q:Q,"<>Closed",'📋 All Notices'!Q:Q,"<>Dropped") -> 0 | L29: =SUMIF('📋 All Notices'!B:B,"*Tamil Nadu*",'📋 All Notices'!O:O) -> 0 | M29: =COUNTIFS('📋 All Notices'!B:B,"*Tamil Nadu*",'📋 All Notices'!Q:Q,"Completed")+COUNTIFS('📋 All Notices'!B:B,"*Tamil Nadu*",'📋 All Notices'!Q:Q,"Closed") -> 0
F30: Telangana | G30: =COUNTIF('📋 All Notices'!B:B,"*Telangana*") -> 2 | H30: =COUNTIFS('📋 All Notices'!B:B,"*Telangana*",'📋 All Notices'!Q:Q,"<>Completed",'📋 All Notices'!Q:Q,"<>Closed",'📋 All Notices'!Q:Q,"<>Dropped") -> 2 | L30: =SUMIF('📋 All Notices'!B:B,"*Telangana*",'📋 All Notices'!O:O) -> 8535414 | M30: =COUNTIFS('📋 All Notices'!B:B,"*Telangana*",'📋 All Notices'!Q:Q,"Completed")+COUNTIFS('📋 All Notices'!B:B,"*Telangana*",'📋 All Notices'!Q:Q,"Closed") -> 0
F31: Uttar Pradesh | G31: =COUNTIF('📋 All Notices'!B:B,"*Uttar Pradesh*") -> 2 | H31: =COUNTIFS('📋 All Notices'!B:B,"*Uttar Pradesh*",'📋 All Notices'!Q:Q,"<>Completed",'📋 All Notices'!Q:Q,"<>Closed",'📋 All Notices'!Q:Q,"<>Dropped") -> 2 | L31: =SUMIF('📋 All Notices'!B:B,"*Uttar Pradesh*",'📋 All Notices'!O:O) -> 48286636 | M31: =COUNTIFS('📋 All Notices'!B:B,"*Uttar Pradesh*",'📋 All Notices'!Q:Q,"Completed")+COUNTIFS('📋 All Notices'!B:B,"*Uttar Pradesh*",'📋 All Notices'!Q:Q,"Closed") -> 0
F32: Uttarakhand | G32: =COUNTIF('📋 All Notices'!B:B,"*Uttarakhand*") -> 0 | H32: =COUNTIFS('📋 All Notices'!B:B,"*Uttarakhand*",'📋 All Notices'!Q:Q,"<>Completed",'📋 All Notices'!Q:Q,"<>Closed",'📋 All Notices'!Q:Q,"<>Dropped") -> 0 | L32: =SUMIF('📋 All Notices'!B:B,"*Uttarakhand*",'📋 All Notices'!O:O) -> 0 | M32: =COUNTIFS('📋 All Notices'!B:B,"*Uttarakhand*",'📋 All Notices'!Q:Q,"Completed")+COUNTIFS('📋 All Notices'!B:B,"*Uttarakhand*",'📋 All Notices'!Q:Q,"Closed") -> 0
F33: West Bengal | G33: =COUNTIF('📋 All Notices'!B:B,"*West Bengal*") -> 4 | H33: =COUNTIFS('📋 All Notices'!B:B,"*West Bengal*",'📋 All Notices'!Q:Q,"<>Completed",'📋 All Notices'!Q:Q,"<>Closed",'📋 All Notices'!Q:Q,"<>Dropped") -> 4 | L33: =SUMIF('📋 All Notices'!B:B,"*West Bengal*",'📋 All Notices'!O:O) -> 39436576 | M33: =COUNTIFS('📋 All Notices'!B:B,"*West Bengal*",'📋 All Notices'!Q:Q,"Completed")+COUNTIFS('📋 All Notices'!B:B,"*West Bengal*",'📋 All Notices'!Q:Q,"Closed") -> 0
A34: ⏰ DUE DATE ALERTS & QUICK STATS
A35: 📅 Due in 7 Days | C35: 🚨 Overdue | E35: 📝 Sec 73 Cases | G35: 📝 Sec 74 Cases | L35: 📝 DGGI Cases
A36: =COUNTIFS('📋 All Notices'!H:H,">="&TODAY(),'📋 All Notices'!H:H,"<="&TODAY()+7,'📋 All Notices'!Q:Q,"<>Completed",'📋 All Notices'!Q:Q,"<>Closed") -> 0 | C36: =COUNTIFS('📋 All Notices'!H:H,"<"&TODAY(),'📋 All Notices'!H:H,"<>",'📋 All Notices'!Q:Q,"<>Completed",'📋 All Notices'!Q:Q,"<>Closed") -> 22 | E36: =COUNTIF('📋 All Notices'!E:E,"*73*") -> 4 | G36: =COUNTIF('📋 All Notices'!E:E,"*74*")-COUNTIF('📋 All Notices'!E:E,"*DGGI*") -> 3 | L36: =COUNTIF('📋 All Notices'!E:E,"*DGGI*") -> 14

Sheet Sheet4

Sheet ⚙️ Sync Log
A1: Timestamp | B1: Status | C1: Details
A2: 46017.658 | B2: Success | C2: Auto-sync
A3: 46017.533 | B3: Success | C3: Auto-sync
A4: 46017.408 | B4: Success | C4: Auto-sync
A5: 46017.283 | B5: Success | C5: Auto-sync
A6: 46017.158 | B6: Success | C6: Auto-sync
A7: 46017.033 | B7: Success | C7: Auto-sync
A8: 46016.908 | B8: Success | C8: Auto-sync
A9: 46016.783 | B9: Success | C9: Auto-sync
A10: 46016.658 | B10: Success | C10: Auto-sync
A11: 46016.533 | B11: Success | C11: Auto-sync
A12: 46016.408 | B12: Success | C12: Auto-sync
A13: 46016.283 | B13: Success | C13: Auto-sync
... A60: 46010.515 | B60: Success | C60: Auto-sync

Sheet Source data official
A1: State | B1: DEMAND ID | C1: Case Id | D1: FY | E1: Section | F1: Original Notice | G1: DUE DATE | H1: DESCRPTION OF CASE | I1: IGST | J1: CGST | K1: SGST | L1: int-igst | M1: int-cgst | N1: int-sgst | O1: Total interest | P1: penalty-igst | Q1: penalty-cgst | R1: penalty-sgst | S1: total penalty | T1: Fee SGST | U1: fee CGST | V1: total fee | W1: TOTAL DEMAND | X1: APPEAL AMT DEPOSITED | Y1: ORDER Status | Z1: REMARKS ON CASE STATUS
A2: Delhi | B2: ZD070725031057H | C2: AD0707250169402 | D2: 2021-22 | E2: DRC-01 | F2: 45856 | G2: 45881 | H2: GST Scrutiny Audit-2021-22 | I2: 134698 | J2: 85503 | K2: 85503 | L2: 92067 | M2: 58442 | N2: 58442 | O2: =L2+M2+N2 -> 208951 | P2: 20000 | Q2: 10000 | R2: 10000 | S2: =P2+Q2+R2 -> 40000 | V2: =T2+U2 -> 0 | W2: =V2+S2+O2+K2+J2+I2 -> 554655 | Y2: Pending Order | Z2: ONLINE REPLY DRC-06 FILED dt.29/07/2025 with details enclosed
A3: DELHI | B3: ZD070925072739O | C3: AD0709250320266 | D3: 2019-20 | E3: DRC-07 | F3: 45930 | G3: 45945 | H3: SCRUTINY OF RETURN FY-2019-20 | I3: 112933 | J3: 8351699 | K3: 8351699 | L3: 121633 | M3: 8995123 | N3: 8995123 | O3: =L3+M3+N3 -> 18111879 | P3: 112933 | Q3: 8351699 | R3: 8351699 | S3: =P3+Q3+R3 -> 16816331 | V3: =T3+U3 -> 0 | W3: =V3+S3+O3+K3+J3+I3 -> 51744541 | Y3: Pending Order | Z3: REPLY DETAILS ANNEXURE FILED ONLINE ON 22/10/2025
A4: DELHI-14 | B4: ZD070824017152N | C4: AD070524056836R | D4: 2019-20 | E4: DRC-07 | F4: 45486 | G4: 45487 | H4: AUDIT SCRUTINY FY-2019-20 | I4: 130091 | J4: 12634437 | K4: 12634437 | L4: 109255 | M4: 10610850 | N4: 10610850 | O4: =L4+M4+N4 -> 21330955 | P4: 20000 | Q4: 1263444 | R4: 1263444 | S4: =P4+Q4+R4 -> 2546888 | T4: 0 | V4: =T4+U4 -> 0 | W4: =V4+S4+O4+K4+J4+I4 -> 49276808 | Y4: Pending Order | Z4: WRIT FILED IN HIGH COURT BY ARCHANA MAAM
A5: HARYANA | B5: ZD060225038336K | C5: AD061124011756D | D5: 2020-21 | E5: DRC-07 | F5: 45715 | G5: 45746 | H5: SCRUTINY OF RETURN FY-2020-21 | I5: 342579 | J5: 139853 | K5: 139853 | L5: 267607 | M5: 109246 | N5: 109246 | O5: =L5+M5+N5 -> 486099 | P5: 34258 | Q5: 38985 | R5: 38985 | S5: =P5+Q5+R5 -> 112228 | T5: 809645 | U5: 809645 | V5: =T5+U5 -> 1619290 | W5: =V5+S5+O5+K5+J5+I5 -> 2839902 | X5: =34258+13986+13986 -> 62230 | Y5: Pending Order | Z5: APPEAL FILED ON 28/06/2025
A6: Haryana HRY-04 | B6: ZD0612230350316 | C6: AD0606230066763 | D6: 2017-18 | E6: DRC-07 | F6: 45291 | G6: 45382 | H6: In response towards the replu Against DRC-01 | I6: 19833242 | J6: 9235140 | K6: =J6 -> 9235140 | L6: 22172902 | M6: 16545672 | N6: 16637234 | O6: =L6+M6+N6 -> 55355808 | P6: 1983324 | Q6: 828245 | R6: =Q6 -> 828245 | S6: =P6+Q6+R6 -> 3639814 | T6: 16475 | U6: 16475 | V6: =T6+U6 -> 32950 | W6: =V6+S6+O6+K6+J6+I6 -> 97332094 | X6: 3830353 | Y6: Pending Order | Z6: GRIVIANCE FILED FOR RE-CONSIDIRATION AGAINST APL-4 (APPEAL REJECTION)
A7: Haryana HRY-07 | B7: ZD060225011119V | C7: AD060824008203G | D7: 2017-18 | E7: DRC-07 | F7: 45509 | G7: 45541 | H7: Cancel dealer ITC Calim of rs. 6671519/- RK Traders | I7: 6671519 | J7: 0 | K7: 0 | L7: 8060657.9 | M7: 0 | N7: 0 | O7: =L7+M7+N7 -> 8060657.9 | P7: 6671519.6 | Q7: 0 | R7: 0 | S7: =P7+Q7+R7 -> 6671519.6 | T7: 0 | V7: =T7+U7 -> 0 | W7: =V7+S7+O7+K7+J7+I7 -> 21403697 | X7: 667152 | Y7: Pending Order | Z7: APPEAL FILED CASE IS PENDING
A8: Himachal Pradesh | B8: ZD0203250056107 | C8: AD0212240011335 | D8: 2024-25 | E8: DRC-07 | F8: 45741 | G8: 45771 | H8: TURNOVER MISMATCH GSTR1 VS GSTR3B FY-2024-25 | J8: 50299 | K8: 50299 | M8: 5281 | N8: 5281 | O8: =L8+M8+N8 -> 10562 | Q8: 5030 | R8: 5030 | S8: =P8+Q8+R8 -> 10060 | V8: =T8+U8 -> 0 | W8: =V8+S8+O8+K8+J8+I8 -> 121220 | Y8: Pending Order | Z8: After DRC-06 REply filed on 07/02/2025 but Dept issued DRC-07 dt.25/03/25
A9: Maharashtra-10 | B9: ZD270324041508G | C9: AD2706240205068 | D9: 2018-19 | E9: DRC-07 | F9: 15/12/2023 | G9: 16/01/2024 | H9: APL -01 Filed on the higlighted notice | I9: 186613 | J9: 1946671 | K9: 1946671 | L9: 201542 | M9: 2102405 | N9: 2102405 | O9: =L9+M9+N9 -> 4406352 | P9: 18661 | Q9: 219667 | R9: 219667 | S9: =P9+Q9+R9 -> 457995 | T9: 0 | V9: =T9+U9 -> 0 | W9: =V9+S9+O9+K9+J9+I9 -> 8944302 | X9: 407998 | Y9: Pending Order | Z9: APPEAL FILED CASE IS PENDING
A10: MAHARASTRA-11 | B10: ZD271224017164R | C10: AD271224006823B | D10: 2022-23 | E10: ASMT-10 | F10: 45631 | G10: 45661 | H10: Intimation of Return Scrutiny FY-2022-23 | J10: =(49425+1163715)/2 -> 606570 | K10: =+J10 -> 606570 | O10: =L10+M10+N10 -> 0 | S10: =P10+Q10+R10 -> 0 | V10: =T10+U10 -> 0 | W10: =V10+S10+O10+K10+J10+I10 -> 1213140 | Y10: Pending Order | Z10: FINAL ORDER PENDING BY DEPT
A11: West Bengal-1 | B11: ZD191223069956V | D11: 2017-18 | E11: DRC-07 | F11: 45290 | G11: =F11+90 -> 45380 | H11: Excess ITC Claimed(AUDIT SCRUTINY FY-2017-18) | J11: 2227492 | K11: =+J11 -> 2227492 | L11: 0 | M11: 0 | N11: 0 | O11: =L11+M11+N11 -> 0 | P11: 0 | Q11: 248749 | R11: =+Q11 -> 248749 | S11: =P11+Q11+R11 -> 497498 | T11: 0 | V11: =T11+U11 -> 0 | W11: =V11+S11+O11+K11+J11+I11 -> 4952482 | X11: 445500 | Y11: Pending Order | Z11: CASE IS UNDER TRIBUNAL APPEALIATE AUTHORITY
A12: West Bengal-2 | B12: ZD191223069958R | D12: 2018-19 | E12: DRC-07 | F12: 45290 | G12: =F12+90 -> 45380 | H12: Short Payment of Tax (AUDIT SCRUTINY FY-2018-19) | J12: 430576 | K12: =+J12 -> 430576 | O12: =L12+M12+N12 -> 0 | Q12: 43058 | R12: =+Q12 -> 43058 | S12: =P12+Q12+R12 -> 86116 | T12: 0 | V12: =T12+U12 -> 0 | W12: =V12+S12+O12+K12+J12+I12 -> 947268 | X12: 86116 | Y12: Pending Order | Z12: CASE IS UNDER TRIBUNAL APPEALIATE AUTHORITY

Sheet 📋 All Notices
A1: 📋 ALL GST NOTICES - IMPRESSIONS SERVICES PVT LTD | X1: RESPONSIBILITY
B2: State | C2: Demand ID | D2: Case ID | E2: DRC-01 (Sec 74 - DGGI) | F2: FY | G2: Issue Date | H2: Due Date | I2: IGST (₹) | J2: CGST (₹) | K2: SGST (₹) | L2: Interest (₹) | M2: Penalty (₹) | N2: Late Fee (₹) | O2: Total Demand (₹) | P2: Appeal Deposited (₹) | Q2: Final Status | R2: Order Status | S2: Description | T2: ISPL Notes | U2: Way Forward | V2: REMARKS | W2: STATUS AS ON DATE
A3: 1 | B3: Delhi | C3: ZD0703260518466 | D3: AD0709250320266 | E3: APL-01 (Appeal Filed) | F3: 2019-20 | H3: 25-03-2026 | I3: 0 | J3: 2530889 | K3: 2530889 | L3: 5466720 | M3: 5061778 | N3: 0 | O3: =I3+J3+K3+L3+M3+N3 -> 15590276 | P3: 506178 | Q3: Active | R3: APPEAL FILED STATUS PENDING | S3: SCRUTINY OF RETURN FY-2019-20 | T3: REPLY DETAILS ANNEXURE FILED ONLINE ON 22/10/2025,no DRC-07 issued till date | U3: DRC-07 ISSUED TO FILE APPEAL | V3: APPEAL FILED STATUS PENDING | X3: Documents to submit in hard copy
A4: =1+A3 -> 2 | B4: Delhi | C4: ZD070824017152N | D4: AD070524056836R | E4: DRC-07 (Sec 73) | F4: 2019-20 | H4: 45487 | I4: 130091 | J4: 12634437 | K4: 12634437 | L4: 21330955 | M4: 2546888 | N4: 0 | O4: =I4+J4+K4+L4+M4+N4 -> 49276808 | Q4: Active | R4: WRIT FILED AT HIGH CRT | S4: AUDIT SCRUTINY FY-2019-20 | T4: WRIT FILED IN HIGH COURT BY ARCHANA MAAM | U4: writ filed and it can be settled outside the court | V4: WRIT FILED AT HIGH CRT | X4: Dcomuts to submit in hard copy
A5: =1+A4 -> 3 | B5: Delhi | C5: ZD070326038075I | D5: AD0703260199702 | E5: DRC-01 (Sec 74) | F5: 2021-22 | H5: 20/04/2026 | L5: =6699+6699 -> 13398 | O5: =I5+J5+K5+L5+M5+N5 -> 13398 | Q5: Closed | R5: Completed | S5: LATE FILING RETURN INTEREST-2021-22 | V5: PAID THRU DRC-03 _AD070426009271E ( DRC07_DROP ORDER_ZD070626013691F DT.10/06/2026 ISSUED)
A6: =1+A5 -> 4 | B6: Delhi | C6: ZD070225002579G | D6: 35/2024-25 | E6: DRC-07 (Sec 74 - DGGI) | F6: 2017-18 | G6: 45690 | H6: 45718 | I6: 9140005 | J6: 18665716 | K6: 18665716 | M6: =9140005+18665716+18665716 -> 46471437 | O6: =I6+J6+K6+L6+M6+N6 -> 92942874 | Q6: Active | R6: WRIT FILED AT HIGH CRT | V6: DELHI HIGH COURT DIARY No 4003818/2025 _WP© DT.02-06-2026
A7: =1+A6 -> 5 | B7: Delhi | C7: ZD070225002581V | D7: 35/2024-25 | E7: DRC-07 (Sec 74 - DGGI) | F7: 2019-20 | G7: 45690 | H7: 45718 | J7: 11259137 | K7: 11259137 | M7: =11259137*2 -> 22518274 | O7: =I7+J7+K7+L7+M7+N7 -> 45036548 | Q7: Active | R7: WRIT FILED AT HIGH CRT | V7: DELHI HIGH COURT DIARY No 4003818/2025 _WP© DT.02-06-2026
A8: =1+A7 -> 6 | B8: Delhi | C8: ZD0712250834287 | D8: AD0707250169402 | E8: APL-01 (Appeal Filed) | F8: 2021-22 | H8: 28-03-2026 | I8: 0 | J8: 31373 | K8: 31373 | L8: =21444+21444 -> 42888 | M8: =10000+10000 -> 20000 | N8: 0 | O8: =I8+J8+K8+L8+M8+N8 -> 125634 | P8: 6274 | Q8: Active | R8: APPEAL FILED,STATUS PENDING | S8: GST Scrutiny Audit-2021-22 | T8: ONLINE REPLY DRC-06 FILED dt.29/07/2025 with details enclosed, DRC-07 issued dt.30/12/2025 | U8: RECTIFICATION REQUEST FILED DT 31/12/2025 AGAINST DRC-07 TO PROTECT ANY PROCEEDINGS | V8: APPEAL FILED,STATUS PENDING
A9: =1+A8 -> 7 | B9: Haryana | C9: ZD0612230350316 | D9: AD0606230066763 | E9: APL-01 (Appeal Filed) | F9: 2017-18 | H9: 45382 | I9: 19833242 | J9: 9235140 | K9: 9235140 | L9: 55355808 | M9: 3639814 | N9: 32950 | O9: =I9+J9+K9+L9+M9+N9 -> 97332094 | P9: 3830353 | Q9: Active | R9: WRIT FILED AT HIGH CRT | S9: In response towards the reply Against DRC-01 (APL-01 REJECTED & APL-04 ISSUED ) | T9: GRIVIANCE FILED FOR RE-CONSIDIRATION AGAINST APL-4 (APPEAL REJECTION) dt.07/01/2025 | U9: GRIVIANCE FILED FOR RE-CONSIDIRATION AGAINST APL-4 (APPEAL REJECTION) dt.07/01/2025 | V9: HIGH COURT FOR THE STATES OF PUNJAB AND HARYANA AT CHANDIGARH _DIARY NO [Miscellaneous - CWP] APB20240004142C202600008 DT.02-06-2026
A10: =1+A9 -> 8 | B10: Haryana | C10: ZD060225011119V | D10: AD060824008203G | E10: APL-01 (Appeal Filed) | F10: 2017-18 | H10: 45541 | I10: 6671519 | J10: 0 | K10: 0 | L10: 8060657.9 | M10: 6671519.6 | N10: 0 | O10: =I10+J10+K10+L10+M10+N10 -> 21403697 | P10: 667152 | Q10: Active | R10: Appeal Filed status pending | S10: Cancel dealer ITC Calim of rs. 6671519/- RK Traders ( APPEAL FILED) | T10: APPEAL FILED ON DT.08/04/2025 WITH APPEAL AMT DEPOSITED ( APL-2 ISSUED) | U10: Appeal filed awaitng for next process by Dept. | V10: APPEAL FILED (Cancel dealer ITC Calim of rs. 6671519/- RK Traders) ,STATUS PENDING | X10: To meet with officer on appeal final processing
A11: =1+A10 -> 9 | B11: Haryana | C11: ZD060824000468F/ZD060125033178N | D11: AD060824000225I | E11: Enforcement Case | F11: 2017-18 | H11: 29-08-2024 | I11: 18807080 | J11: 0 | K11: 0 | L11: 0 | M11: 18807080 | N11: 0 | O11: =I11+J11+K11+L11+M11+N11 -> 37614160 | Q11: Active | R11: Reply Filed DRC-03 payment made | S11: Cancel dealer ITC Calim of M/S Dhanaasha Infracon_FY-2017-18 | V11: REPLY FILED WITH DRC-03 PAYMENT M/S.DHANAASHA INFRACON ),CONDONATION APPEAL TO FILE
A12: =1+A11 -> 10 | B12: Haryana | C12: ZD0612250705787 | D12: AD0606250204096 | E12: DRC-07 (Sec 74) | F12: 2018-19 | H12: 30-12-2025 | L12: =32565+32565 -> 65130 | O12: =I12+J12+K12+L12+M12+N12 -> 65130 | Q12: Active | R12: Reply Filed tax paid interest pending | S12: Cancel dealer ITC Calim of rs. 723975/ OF HEMU OVERSEAS | V12: TAX AMOUNT SETTLED BUT INTREST PENDING AS THIS IS A DGGI MATTER_ITC Calim of rs. 723975/ OF HEMU OVERSEAS | X12: himanshu Dubey
A13: =1+A12 -> 11 | B13: Haryana | C13: ZD061225065921F | D13: AD0606250262755 | E13: APL-01 (Appeal Filed) | F13: 2018-19 | H13: 30-01-2026 | I13: 86220 | J13: 0 | K13: 0 | L13: 0 | M13: 86220 | N13: 0 | O13: =I13+J13+K13+L13+M13+N13 -> 172440 | P13: 8622 | Q13: Active | R13: Appeal Filed status pending | S13: Cancel dealer ITC Calim of rs. 86220/- RADHEY ENTERPRISES -2018-19 | T13: ( RECTIFICATION AGAINST ORDER FILED) DT.08-01-2026 | U13: HAD A MEETING WITH AC/ EAST-2 CGST GGN ON 21/01/2026 WILL VISIT AGAIN TO REVIEW ON THIS MATTER | V13: APPEAL FILED (Cancel dealer ITC Calim of IGST RS. 86220/ OF RADHEY ENTERPRISES-07BZEPG9648C1IE) STATUS PENDING
A14: =1+A13 -> 12 | B14: Haryana | C14: ZD060225038336K | D14: AD061124011756D | E14: APL-01 (Appeal Filed) | F14: 2020-21 | H14: 45746 | I14: 342579 | J14: 139853 | K14: 139853 | L14: 486099 | M14: 112228 | N14: 1619290 | O14: =I14+J14+K14+L14+M14+N14 -> 2839902 | P14: 62230 | Q14: Active | R14: APPEAL-2 TO FILE ON GSTAT URGENTLY BY 31/07/2026 | S14: SCRUTINY OF RETURN FY-2020-21 (APPEAL FILED) | T14: DRC-07 ORDER ISSUED AGAINST OUR REPLY FILED .Appeal _APL-01 FILED DT.28/06/25 WITH DEPOSITED AMT.62230/- no APL-04 issued till date | U14: Appeal filed awaitng for next process by Dept. | V14: APPEAL-2 TO FILE ON GSTAT URGENTLY BY 31/07/2026 (SHARED IN GROUP COURT FEES RS.25000/- DEPOSITED FOR GSTAT ) PENDING @ DISHANT JI | X14: AK DASH | Y14: reply till 12/06/2026
A15: =1+A14 -> 13 | B15: Haryana | C15: ZD060925054064D | D15: AD060425016525A | E15: GST AUDIT | F15: 2021-22 | H15: 29-10-2025 | I15: 12987 | J15: 30594 | K15: 30594 | L15: 98546 | N15: 0 | O15: =I15+J15+K15+L15+M15+N15 -> 172721 | Q15: Closed | R15: closed order passed | S15: SCRUTINY OF RETURN GST AUDIT FY-2021-22 | V15: DRC-01 TO PAY AS PER ADT-2 FINAL DEMAND PAID RS.172721/- THRU DRC-03 DT.09/10/25 (Closed order passed) | X15: AK DASH | Y15: reply till 12/06/2026
A16: =1+A15 -> 14 | B16: Haryana | C16: ZD060425033442Q/ ZD060526036133O | D16: AD0604250165268 | E16: DRC-01 (Sec 73) | F16: 2022-23 | G16: 46169 | H16: 26-06-2026 | J16: 253585 | K16: 253585 | L16: =1615642+274319+274319 -> 2164280 | M16: =25358+25358 -> 50716 | N16: 0 | O16: =I16+J16+K16+L16+M16+N16 -> 2722166 | Q16: Active | R16: ADT-2 REPLY FILED ON 27/06/2026 deptt response awaited | S16: SCRUTINY OF RETURN GST AUDIT | V16: ADT-2 REPLY FILED ON 27/06/2026 as per review BY DISHANT JI | W16: REPLY DRAFT SENT TO DISHANT JI FOR APPROVAL ON 17/06/26 THRU WHATTSAAP | X16: AK DASH
A17: =1+A16 -> 15 | B17: Haryana | C17: ZD060825031852B / ZD060526036222P | D17: AD060425016524C | E17: DRC-01 (Sec 73) | F17: 2023-24 | G17: 46169 | H17: 26-06-2026 | I17: 375079 | J17: 281010 | K17: 281010 | L17: =1125560+253645+253645 -> 1632850 | M17: =37508+28100+28100 -> 93708 | O17: =I17+J17+K17+L17+M17+N17 -> 2663657 | Q17: Active | R17: ADT-2 REPLY FILED ON 27/06/2026 as per review BY DISHANT JI | S17: SCRUTINY OF RETURN GST AUDIT | V17: ADT-2 REPLY FILED ON 27/06/2026 as per review BY DISHANT JI
A18: =1+A17 -> 16 | B18: Haryana | C18: ZD060225001319T | D18: 35/2024-25 | E18: DRC-07 (Sec 74 - DGGI) | F18: 2020-21 | G18: 45690 | H18: 45718 | I18: 449696 | M18: 449696 | O18: =I18+J18+K18+L18+M18+N18 -> 899392 | Q18: Active | R18: WRIT FILED AT HIGH CRT | V18: DELHI HIGH COURT DIARY No 4003818/2025 _WP© DT.02-06-2026
A19: =1+A18 -> 17 | B19: Haryana | C19: ZD0602250013127 | D19: 35/2024-25 | E19: DRC-07 (Sec 74 - DGGI) | F19: 2017-18 | G19: 45690 | H19: 45718 | I19: 33973494 | J19: 13805337 | K19: 13805216 | M19: =33973494+13805337+13805337 -> 61584168 | O19: =I19+J19+K19+L19+M19+N19 -> 123168215 | Q19: Active | R19: WRIT FILED AT HIGH CRT | V19: DELHI HIGH COURT DIARY No 4003818/2025 _WP© DT.02-06-2026
A20: =1+A19 -> 18 | B20: Himachal Pradesh | C20: ZD0203250056107 | D20: AD0212240011335 | E20: APL-01 (Appeal Filed) | F20: 2024-25 | H20: 45771 | J20: 50299 | K20: 50299 | L20: 10562 | M20: 10060 | N20: 0 | O20: =I20+J20+K20+L20+M20+N20 -> 121220 | P20: 10060 | Q20: Active | R20: APPEAL WITH CONDONATION FILED STATUS PENDING | S20: TURNOVER MISMATCH GSTR1 VS GSTR3B FY-2024-25 | T20: After DRC-06 REply filed on 07/02/2025 but Dept issued DRC-07 dt.25/03/25.Greiviance of Rectification Request filed dt.29/12/2025 | U20: To be pursue by CA Himanshu Dubey | V20: APPEAL WITH CONDONATION FILED STATUS PENDING
A21: =1+A20 -> 19 | B21: Jharkhand | C21: ZD200225000242H | D21: 35/2024-25 | E21: DRC-07 (Sec 74 - DGGI) | F21: 2018-19 | G21: 45690 | H21: 45718 | J21: 2454 | K21: 2454 | M21: =2454*2 -> 4908 | O21: =I21+J21+K21+L21+M21+N21 -> 9816 | Q21: Active | R21: WRIT FILED AT HIGH CRT | V21: DELHI HIGH COURT DIARY No 4003818/2025 _WP© DT.02-06-2026
A22: =1+A21 -> 20 | B22: Karnataka | C22: ZD290225003751N | D22: 35/2024-25 | E22: DRC-07 (Sec 74 - DGGI) | F22: 2020-21 | G22: 45690 | H22: 45718 | J22: 66023 | K22: 66023 | M22: =66023*2 -> 132046 | O22: =I22+J22+K22+L22+M22+N22 -> 264092 | Q22: Active | R22: WRIT FILED AT HIGH CRT | V22: DELHI HIGH COURT DIARY No 4003818/2025 _WP© DT.02-06-2026
A23: =1+A22 -> 21 | B23: Kerala | C23: ZD3202250010459 | D23: 35/2024-25 | E23: DRC-07 (Sec 74 - DGGI) | F23: 2018-19 | G23: 45690 | H23: 45718 | I23: 11351 | M23: 11351 | O23: =I23+J23+K23+L23+M23+N23 -> 22702 | Q23: Active | R23: WRIT FILED AT HIGH CRT | V23: DELHI HIGH COURT DIARY No 4003818/2025 _WP© DT.02-06-2026
A24: =1+A23 -> 22 | B24: Maharashtra | C24: ZD270324041508G | D24: AD2706240205068 | E24: APL-01 (Appeal Filed) | F24: 2018-19 | H24: 16/01/2024 | I24: 186613 | J24: 1946671 | K24: 1946671 | L24: 4406352 | M24: 457995 | N24: 0 | O24: =I24+J24+K24+L24+M24+N24 -> 8944302 | P24: 407998 | Q24: Active | R24: Appeal Filed underprocess | S24: Already we have filed online & ofline supported docs but GST Dept declined all these and issued DRC-07 dt.19-03-24 against which we have filed Appeal taht has been admited by dept. | T24: APPEAL FILED & APL-2 ISSUED BY DEPT | U24: under negotiation being followed by Brijmohan ji paper submmitted today | V24: APPEAL FILED AND HEARING UNDER PROCESS TO HANDEL BY HITESH JI | W24: FINAL APPEAL DOCUMENTS to PRODUCE
A25: =1+A24 -> 23 | B25: Maharashtra | C25: ZD271224017164R | D25: AD271224006823B | E25: ASMT-10 (Scrutiny) | F25: 2022-23 | G25: 45631 | H25: 45661 | J25: 606570 | K25: 606570 | L25: 0 | M25: 0 | N25: 0 | O25: =I25+J25+K25+L25+M25+N25 -> 1213140 | Q25: Completed | R25: Order Pending | S25: Intimation of Return Scrutiny FY-2022-23 | T25: FINAL ORDER AWAITING FROM DEPT | U25: meeting on 07/01/2026 in mumbai | V25: REPLY FILED IN DETAILS SUPPORTED COPY ALONG WITH DRC-03 PAYAMENT
A26: =1+A25 -> 24 | B26: Maharashtra | C26: ZD270225002570W | D26: 35/2024-25 | E26: DRC-07 (Sec 74 - DGGI) | F26: 2017-18 | G26: 45690 | H26: 45718 | I26: 12234980 | M26: 12234980 | O26: =I26+J26+K26+L26+M26+N26 -> 24469960 | Q26: Active | R26: WRIT FILED AT HIGH CRT | V26: DELHI HIGH COURT DIARY No 4003818/2025 _WP© DT.02-06-2026 | X26: DGGI WRIT ACKNOWLEDGEMENT REQUIRE
A27: =1+A26 -> 25 | B27: Rajasthan | C27: ZD080225000863N | D27: 35/2024-25 | E27: DRC-07 (Sec 74 - DGGI) | F27: 2017-18 | G27: 45690 | H27: 45718 | J27: 136515 | K27: 136515 | M27: =136515*2 -> 273030 | O27: =I27+J27+K27+L27+M27+N27 -> 546060 | Q27: Active | R27: WRIT FILED AT HIGH CRT | V27: DELHI HIGH COURT DIARY No 4003818/2025 _WP© DT.02-06-2026 | X27: DGGI WRIT ACKNOWLEDGEMENT REQUIRE
A28: =1+A27 -> 26 | B28: TAMILNADU | C28: ZD3304261712995 | D28: AD330426043759T | E28: DRC-01 (Sec 73) | F28: 2023-24 | G28: 20-04-2026 | H28: 19-05-2026 | I28: 203854 | J28: 589029 | K28: 589029 | L28: 496807 | M28: 138231 | O28: =I28+J28+K28+L28+M28+N28 -> 2016950 | Q28: Active | R28: ONLINE REPLY FILED_DRC-06 STATUS YET PENDING | S28: SCRUTINY OF RETURN GST AUDIT | V28: ONLINE REPLY FILED_DRC-06 STATUS YET PENDING | X28: DGGI WRIT ACKNOWLEDGEMENT REQUIRE
A29: =1+A28 -> 27 | B29: TELANGANA | C29: ZD360526020645E | E29: ASMT-10 (Scrutiny) | F29: 2022-23 | G29: 46154 | H29: 46185 | I29: 2739468 | J29: 2198255 | K29: 2198255 | O29: =I29+J29+K29+L29+M29+N29 -> 7135978 | Q29: Active | R29: Reply Filed | V29: REPLY FILED IN DETAILS SUPPORTED COPY ALONG WITH DRC-03 PAYAMENT ON 12/06/2026,STATUS AWAITING
A30: =1+A29 -> 28 | B30: Telangana | C30: ZD360225002383U | D30: 35/2024-25 | E30: DRC-07 (Sec 74 - DGGI) | F30: 2018-19 | G30: 45690 | H30: 45718 | I30: 160138 | J30: 269790 | K30: 269790 | M30: =160138+269790+269790 -> 699718 | O30: =I30+J30+K30+L30+M30+N30 -> 1399436 | Q30: Active | R30: WRIT FILED AT HIGH CRT | V30: DELHI HIGH COURT DIARY No 4003818/2025 _WP© DT.02-06-2026 | X30: DGGI WRIT ACKNOWLEDGEMENT REQUIRE
A31: =1+A30 -> 29 | B31: Uttar Pradesh | C31: ZD090225012652O | D31: 35/2024-25 | E31: DRC-07 (Sec 74 - DGGI) | F31: 2017-18 | G31: 45690 | H31: 45718 | I31: 12620360 | J31: 5319352 | K31: 5319352 | M31: =12620360+5319352+5319352 -> 23259064 | O31: =I31+J31+K31+L31+M31+N31 -> 46518128 | Q31: Active | R31: WRIT FILED AT HIGH CRT | V31: DELHI HIGH COURT DIARY No 4003818/2025 _WP© DT.02-06-2026 | X31: DGGI WRIT ACKNOWLEDGEMENT REQUIRE
A32: =1+A31 -> 30 | B32: Uttar Pradesh | C32: ZD090225012656G | D32: 35/2024-25 | E32: DRC-07 (Sec 74 - DGGI) | F32: 2018-19 | G32: 45690 | H32: 45718 | I32: 884254 | M32: 884254 | O32: =I32+J32+K32+L32+M32+N32 -> 1768508 | Q32: Active | R32: Reply Filed status pending | V32: DELHI HIGH COURT DIARY No 4003818/2025 _WP© DT.02-06-2026 | X32: DGGI WRIT ACKNOWLEDGEMENT REQUIRE
A33: =1+A32 -> 31 | B33: West Bengal | C33: ZD191223069956V | E33: APL-01 (Appeal Filed) | F33: 2017-18 | H33: 45380 | J33: 2227492 | K33: 2227492 | L33: 0 | M33: 497498 | N33: 0 | O33: =I33+J33+K33+L33+M33+N33 -> 4952482 | P33: 445500 | Q33: Active | R33: HEARING ATTENDED NOW CASE UNDER Appellate Tribunal | S33: Excess ITC Claimed(AUDIT SCRUTINY FY-2017-18) APL-01 FILED & HEARING APPEARED BEFORE APPEALIATE AUTHORITY | T33: CASE IS UNDER TRIBUNAL APPEALIATE AUTHORITY | U33: Had a telecon with Authority regarding appeal process awaiting his confirmation | V33: HEARING ATTENDED NOW CASE UNDER Appellate Tribunal | X33: DGGI WRIT ACKNOWLEDGEMENT REQUIRE
A34: =1+A33 -> 32 | B34: West Bengal | C34: ZD191223069958R | E34: APL-01 (Appeal Filed) | F34: 2018-19 | H34: 45380 | J34: 430576 | K34: 430576 | L34: 0 | M34: 86116 | N34: 0 | O34: =I34+J34+K34+L34+M34+N34 -> 947268 | P34: 86116 | Q34: Active | R34: HEARING ATTENDED NOW CASE UNDER Appellate Tribunal | S34: Short Payment of Tax (AUDIT SCRUTINY FY-2018-19) APL-01 FILED & HEARING APPEARED BEFORE APPEALIATE AUTHORITY | T34: CASE IS UNDER TRIBUNAL APPEALIATE AUTHORITY | U34: Had a telecon with Authority regarding appeal process awaiting his confirmation | V34: HEARING ATTENDED NOW CASE UNDER Appellate Tribunal | X34: DGGI WRIT ACKNOWLEDGEMENT REQUIRE
A35: =1+A34 -> 33 | B35: West Bengal | C35: ZD190225002834J/ ZD190625056607Y | D35: AD190824004645X | E35: DRC-07 (Sec 74) | F35: 2017-18 | G35: 45692 | H35: 45718 | J35: 927509 | K35: 927509 | M35: 1855018 | O35: =I35+J35+K35+L35+M35+N35 -> 3710036 | Q35: Active | R35: RECTIFICATION REJECTED to take action | V35: DHANAASHA INFRACON ENFORCEMENT_2017-18 (RECTIFICATION REJEC TED BY DEPT) NEED URGENT ACTION TO FILE APPEAL WITH CONDONATION | X35: DGGI WRIT ACKNOWLEDGEMENT REQUIRE
A36: =1+A35 -> 34 | B36: West Bengal | C36: ZD190225000734N | D36: 35/2024-25 | E36: DRC-07 (Sec 74 - DGGI) | F36: 2017-18 | G36: 45690 | H36: 45718 | I36: 6751699 | J36: 4080848 | K36: 4080848 | M36: =6751699+4080848+4080848 -> 14913395 | O36: =I36+J36+K36+L36+M36+N36 -> 29826790 | Q36: Active | R36: DELHI HIGH COURT DIARY No 4003818/2025 _WP© DT.02-06-2026 | V36: DELHI HIGH COURT DIARY No 4003818/2025 _WP© DT.02-06-2026 | X36: DGGI WRIT ACKNOWLEDGEMENT REQUIRE

Sheet Sheet1

Sheet 📈 Analytics
A1: 📈 GST NOTICE ANALYTICS - IMPRESSIONS SERVICES PVT LTD
A2: 🕐 Last Updated: | B2: =NOW() -> 46221.297
A4: 📊 OVERALL SUMMARY
A5: 📋 Total Notices | B5: 🏷️ Tax Demand | C5: 💰 Total Demand | F5: 💵 Interest | G5: ⚠️ Penalty | H5: 📋 Late Fee | J5: 🏦 Appeal Deposited | K5: 🔴 Active Cases
A6: 11 | B6: =SUM('📋 All Notices'!I3:I1006)+SUM('📋 All Notices'!J3:J1006)+SUM('📋 All Notices'!K3:K1006) -> 301051496 | C6: =SUM('📋 All Notices'!O3:O1006) -> 6.2590598e+08 | F6: =SUM('📋 All Notices'!L3:L1006) -> 99631053 | G6: =SUM('📋 All Notices'!M3:M1006) -> 2.2357119e+08 | H6: =SUM('📋 All Notices'!N3:N1006) -> 1652240 | J6: =SUM('📋 All Notices'!P3:P1006) -> 6030483 | K6: =COUNTIF('📋 All Notices'!Q3:Q1006,"*Active*") -> 31
A9: 📊 STATUS SUMMARY | F9: 📈 CASE TYPE ANALYSIS | J9: 📅 FY-WISE BREAKDOWN
A10: Status | B10: Count | C10: Tax Demand | D10: Total Demand | F10: Case Type | G10: Count | H10: Total Demand | J10: Financial Year | K10: Count | L10: Tax Demand | M10: Total Demand
A11: Active | B11: =COUNTIF('📋 All Notices'!Q3:Q1006,"*Active*") -> 31 | C11: =SUMIF('📋 All Notices'!Q3:Q1006,"*Active*",'📋 All Notices'!I3:I1006)+SUMIF('📋 All Notices'!Q3:Q1006,"*Active*",'📋 All Notices'!J3:J1006)+SUMIF('📋 All Notices'!Q3:Q1006,"*Active*",'📋 All Notices'!K3:K1006) -> 299764181 | D11: =SUMIF('📋 All Notices'!Q3:Q1006,"*Active*",'📋 All Notices'!O3:O1006) -> 6.2450672e+08 | F11: DRC-01 (Sec 73) | G11: =COUNTIF('📋 All Notices'!E3:E1006,"*DRC-01*") -> 4 | H11: =SUMIF('📋 All Notices'!E3:E1006,"*DRC-01*",'📋 All Notices'!O3:O1006) -> 7416171 | J11: 2024-25 | K11: =COUNTIF('📋 All Notices'!F3:F1006,"*2024-25*") -> 1 | L11: =SUMIF('📋 All Notices'!F3:F1006,"*2024-25*",'📋 All Notices'!I3:I1006)+SUMIF('📋 All Notices'!F3:F1006,"*2024-25*",'📋 All Notices'!J3:J1006)+SUMIF('📋 All Notices'!F3:F1006,"*2024-25*",'📋 All Notices'!K3:K1006) -> 100598 | M11: =SUMIF('📋 All Notices'!F3:F1006,"*2024-25*",'📋 All Notices'!O3:O1006) -> 121220
A12: Completed | B12: =COUNTIF('📋 All Notices'!Q3:Q1006,"*Completed*") -> 1 | C12: =SUMIF('📋 All Notices'!Q3:Q1006,"*Completed*",'📋 All Notices'!I3:I1006)+SUMIF('📋 All Notices'!Q3:Q1006,"*Completed*",'📋 All Notices'!J3:J1006)+SUMIF('📋 All Notices'!Q3:Q1006,"*Completed*",'📋 All Notices'!K3:K1006) -> 1213140 | D12: =SUMIF('📋 All Notices'!Q3:Q1006,"*Completed*",'📋 All Notices'!O3:O1006) -> 1213140 | F12: APL-01 (Appeal Filed) | G12: 6 | H12: =SUMIF('📋 All Notices'!E3:E1006,"APL-01 (Appeal Filed)",'📋 All Notices'!O3:O1006) -> 1.5242931e+08 | J12: 2023-24 | K12: =COUNTIF('📋 All Notices'!F3:F1006,"*2023-24*") -> 2 | L12: =SUMIF('📋 All Notices'!F3:F1006,"*2023-24*",'📋 All Notices'!I3:I1006)+SUMIF('📋 All Notices'!F3:F1006,"*2023-24*",'📋 All Notices'!J3:J1006)+SUMIF('📋 All Notices'!F3:F1006,"*2023-24*",'📋 All Notices'!K3:K1006) -> 2319011 | M12: =SUMIF('📋 All Notices'!F3:F1006,"*2023-24*",'📋 All Notices'!O3:O1006) -> 4680607
A13: Under Appeal | B13: =COUNTIF('📋 All Notices'!R3:R1006,"*Appeal Filed*") -> 5 | C13: =SUMIF('📋 All Notices'!Q3:Q1006,"*Under Appeal*",'📋 All Notices'!I3:I1006)+SUMIF('📋 All Notices'!Q3:Q1006,"*Under Appeal*",'📋 All Notices'!J3:J1006)+SUMIF('📋 All Notices'!Q3:Q1006,"*Under Appeal*",'📋 All Notices'!K3:K1006) -> 0 | D13: =SUMIF('📋 All Notices'!R3:R1006,"*Appeal Filed*",'📋 All Notices'!O3:O1006) -> 46236349 | F13: DRC-01B | G13: =COUNTIF('📋 All Notices'!E3:E1006,"*DRC-01B*") -> 0 | H13: =SUMIF('📋 All Notices'!E3:E1006,"*DRC-01B*",'📋 All Notices'!O3:O1006) -> 0 | J13: 2022-23 | K13: =COUNTIF('📋 All Notices'!F3:F1006,"*2022-23*") -> 3 | L13: =SUMIF('📋 All Notices'!F3:F1006,"*2022-23*",'📋 All Notices'!I3:I1006)+SUMIF('📋 All Notices'!F3:F1006,"*2022-23*",'📋 All Notices'!J3:J1006)+SUMIF('📋 All Notices'!F3:F1006,"*2022-23*",'📋 All Notices'!K3:K1006) -> 8856288 | M13: =SUMIF('📋 All Notices'!F3:F1006,"*2022-23*",'📋 All Notices'!O3:O1006) -> 11071284
A14: Dropped | B14: =COUNTIF('📋 All Notices'!Q3:Q1006,"*Dropped*") -> 0 | C14: =SUMIF('📋 All Notices'!Q3:Q1006,"*Dropped*",'📋 All Notices'!I3:I1006)+SUMIF('📋 All Notices'!Q3:Q1006,"*Dropped*",'📋 All Notices'!J3:J1006)+SUMIF('📋 All Notices'!Q3:Q1006,"*Dropped*",'📋 All Notices'!K3:K1006) -> 0 | D14: =SUMIF('📋 All Notices'!Q3:Q1006,"*Dropped*",'📋 All Notices'!O3:O1006) -> 0 | F14: DRC-03 | G14: =COUNTIF('📋 All Notices'!E3:E1006,"*DRC-03*") -> 0 | H14: =SUMIF('📋 All Notices'!E3:E1006,"*DRC-03*",'📋 All Notices'!O3:O1006) -> 0 | J14: 2021-22 | K14: =COUNTIF('📋 All Notices'!F3:F1006,"*2021-22*") -> 3 | L14: =SUMIF('📋 All Notices'!F3:F1006,"*2021-22*",'📋 All Notices'!I3:I1006)+SUMIF('📋 All Notices'!F3:F1006,"*2021-22*",'📋 All Notices'!J3:J1006)+SUMIF('📋 All Notices'!F3:F1006,"*2021-22*",'📋 All Notices'!K3:K1006) -> 136921 | M14: =SUMIF('📋 All Notices'!F3:F1006,"*2021-22*",'📋 All Notices'!O3:O1006) -> 311753
A15: Pending Order | B15: =COUNTIF('📋 All Notices'!R3:R1006,"*Order Pending*") -> 1 | C15: =SUMIF('📋 All Notices'!Q3:Q1006,"*Pending Reply*",'📋 All Notices'!I3:I1006)+SUMIF('📋 All Notices'!Q3:Q1006,"*Pending Reply*",'📋 All Notices'!J3:J1006)+SUMIF('📋 All Notices'!Q3:Q1006,"*Pending Reply*",'📋 All Notices'!K3:K1006) -> 0 | D15: =SUMIF('📋 All Notices'!R3:R1006,"*Order Pending*",'📋 All Notices'!O3:O1006) -> 1213140 | F15: DRC-07 (Sec 73) | G15: =COUNTIF('📋 All Notices'!E3:E1006,"*DRC-07*") -> 16 | H15: =SUMIF('📋 All Notices'!E3:E1006,"*DRC-07*",'📋 All Notices'!O3:O1006) -> 419924495 | J15: 2020-21 | K15: =COUNTIF('📋 All Notices'!F3:F1006,"*2020-21*") -> 3 | L15: =SUMIF('📋 All Notices'!F3:F1006,"*2020-21*",'📋 All Notices'!I3:I1006)+SUMIF('📋 All Notices'!F3:F1006,"*2020-21*",'📋 All Notices'!J3:J1006)+SUMIF('📋 All Notices'!F3:F1006,"*2020-21*",'📋 All Notices'!K3:K1006) -> 1204027 | M15: =SUMIF('📋 All Notices'!F3:F1006,"*2020-21*",'📋 All Notices'!O3:O1006) -> 4003386
A16: Order Issued | B16: =COUNTIF('📋 All Notices'!R3:R1006,"Order Issued") -> 0 | C16: =COUNTIF('📋 All Notices'!S3:S1006,"Order Issued") -> 0 | D16: =SUMIF('📋 All Notices'!R3:R1007,"*Order Issued*",'📋 All Notices'!O3:O1006) -> 0 | F16: ASMT-10 | G16: =COUNTIF('📋 All Notices'!E3:E1006,"*ASMT-10*") -> 2 | H16: =SUMIF('📋 All Notices'!E3:E1006,"*ASMT-10*",'📋 All Notices'!O3:O1006) -> 8349118 | J16: 2019-20 | K16: =COUNTIF('📋 All Notices'!F3:F1006,"*2019-20*") -> 3 | L16: =SUMIF('📋 All Notices'!F3:F1006,"*2019-20*",'📋 All Notices'!I3:I1006)+SUMIF('📋 All Notices'!F3:F1006,"*2019-20*",'📋 All Notices'!J3:J1006)+SUMIF('📋 All Notices'!F3:F1006,"*2019-20*",'📋 All Notices'!K3:K1006) -> 52979017 | M16: =SUMIF('📋 All Notices'!F3:F1006,"*2019-20*",'📋 All Notices'!O3:O1006) -> 109903632
A17: TOTAL | B17: =SUM(B11:B16) -> 38 | C17: =SUM(C11:C16) -> 300977321 | D17: =SUM(D11:D16) -> 6.7316935e+08 | F17: MOV-09 | G17: =COUNTIF('📋 All Notices'!E3:E1006,"*MOV-09*") -> 0 | H17: =SUMIF('📋 All Notices'!E3:E1006,"*MOV-09*",'📋 All Notices'!O3:O1006) -> 0 | J17: 2018-19 | K17: =COUNTIF('📋 All Notices'!F3:F1006,"*2018-19*") -> 8 | L17: =SUMIF('📋 All Notices'!F3:F1006,"*2018-19*",'📋 All Notices'!I3:I1006)+SUMIF('📋 All Notices'!F3:F1006,"*2018-19*",'📋 All Notices'!J3:J1006)+SUMIF('📋 All Notices'!F3:F1006,"*2018-19*",'📋 All Notices'!K3:K1006) -> 6627558 | M17: =SUMIF('📋 All Notices'!F3:F1006,"*2018-19*",'📋 All Notices'!O3:O1006) -> 13329602
F18: TOTAL | G18: =SUM(G11:G17) -> 28 | H18: =SUM(H11:H17) -> 5.881191e+08 | J18: 2017-18 | K18: =COUNTIF('📋 All Notices'!F3:F1006,"*2017-18*") -> 11 | L18: =SUMIF('📋 All Notices'!F3:F1006,"*2017-18*",'📋 All Notices'!I3:I1006)+SUMIF('📋 All Notices'!F3:F1006,"*2017-18*",'📋 All Notices'!J3:J1006)+SUMIF('📋 All Notices'!F3:F1006,"*2017-18*",'📋 All Notices'!K3:K1006) -> 228828076 | M18: =SUMIF('📋 All Notices'!F3:F1006,"*2017-18*",'📋 All Notices'!O3:O1006) -> 4.824845e+08
J19: TOTAL | K19: =SUM(K11:K18) -> 34 | L19: =SUM(L11:L18) -> 301051496 | M19: =SUM(M11:M18) -> 6.2590598e+08
A22: 🏛️ STATE-WISE SUMMARY
A23: State | B23: Cases | C23: IGST | D23: CGST | E23: SGST | F23: Tax Demand | G23: Interest | H23: Penalty | I23: Late Fee | J23: Total Demand | K23: Appeal Dep. | L23: Active
A24: Andhra Pradesh | B24: =COUNTIF('📋 All Notices'!B3:B1006,"*Andhra Pradesh*") -> 0 | C24: =SUMIF('📋 All Notices'!B3:B1006,"*Andhra Pradesh*",'📋 All Notices'!I3:I1006) -> 0 | D24: =SUMIF('📋 All Notices'!B3:B1006,"*Andhra Pradesh*",'📋 All Notices'!J3:J1006) -> 0 | E24: =SUMIF('📋 All Notices'!B3:B1006,"*Andhra Pradesh*",'📋 All Notices'!K3:K1006) -> 0 | F24: =C24+D24+E24 -> 0 | G24: =SUMIF('📋 All Notices'!B3:B1006,"*Andhra Pradesh*",'📋 All Notices'!L3:L1006) -> 0 | H24: =SUMIF('📋 All Notices'!B3:B1006,"*Andhra Pradesh*",'📋 All Notices'!M3:M1006) -> 0 | I24: =SUMIF('📋 All Notices'!B3:B1006,"*Andhra Pradesh*",'📋 All Notices'!N3:N1006) -> 0 | J24: =SUMIF('📋 All Notices'!B3:B1006,"*Andhra Pradesh*",'📋 All Notices'!O3:O1006) -> 0 | K24: =SUMIF('📋 All Notices'!B3:B1006,"*Andhra Pradesh*",'📋 All Notices'!P3:P1006) -> 0 | L24: =COUNTIFS('📋 All Notices'!B3:B1006,"*Andhra Pradesh*",'📋 All Notices'!Q3:Q1006,"*Active*") -> 0
A25: Assam | B25: =COUNTIF('📋 All Notices'!B3:B1006,"*Assam*") -> 0 | C25: =SUMIF('📋 All Notices'!B3:B1006,"*Assam*",'📋 All Notices'!I3:I1006) -> 0 | D25: =SUMIF('📋 All Notices'!B3:B1006,"*Assam*",'📋 All Notices'!J3:J1006) -> 0 | E25: =SUMIF('📋 All Notices'!B3:B1006,"*Assam*",'📋 All Notices'!K3:K1006) -> 0 | F25: =C25+D25+E25 -> 0 | G25: =SUMIF('📋 All Notices'!B3:B1006,"*Assam*",'📋 All Notices'!L3:L1006) -> 0 | H25: =SUMIF('📋 All Notices'!B3:B1006,"*Assam*",'📋 All Notices'!M3:M1006) -> 0 | I25: =SUMIF('📋 All Notices'!B3:B1006,"*Assam*",'📋 All Notices'!N3:N1006) -> 0 | J25: =SUMIF('📋 All Notices'!B3:B1006,"*Assam*",'📋 All Notices'!O3:O1006) -> 0 | K25: =SUMIF('📋 All Notices'!B3:B1006,"*Assam*",'📋 All Notices'!P3:P1006) -> 0 | L25: =COUNTIFS('📋 All Notices'!B3:B1006,"*Assam*",'📋 All Notices'!Q3:Q1006,"*Active*") -> 0
A26: Bihar | B26: =COUNTIF('📋 All Notices'!B3:B1006,"*Bihar*") -> 0 | C26: =SUMIF('📋 All Notices'!B3:B1006,"*Bihar*",'📋 All Notices'!I3:I1006) -> 0 | D26: =SUMIF('📋 All Notices'!B3:B1006,"*Bihar*",'📋 All Notices'!J3:J1006) -> 0 | E26: =SUMIF('📋 All Notices'!B3:B1006,"*Bihar*",'📋 All Notices'!K3:K1006) -> 0 | F26: =C26+D26+E26 -> 0 | G26: =SUMIF('📋 All Notices'!B3:B1006,"*Bihar*",'📋 All Notices'!L3:L1006) -> 0 | H26: =SUMIF('📋 All Notices'!B3:B1006,"*Bihar*",'📋 All Notices'!M3:M1006) -> 0 | I26: =SUMIF('📋 All Notices'!B3:B1006,"*Bihar*",'📋 All Notices'!N3:N1006) -> 0 | J26: =SUMIF('📋 All Notices'!B3:B1006,"*Bihar*",'📋 All Notices'!O3:O1006) -> 0 | K26: =SUMIF('📋 All Notices'!B3:B1006,"*Bihar*",'📋 All Notices'!P3:P1006) -> 0 | L26: =COUNTIFS('📋 All Notices'!B3:B1006,"*Bihar*",'📋 All Notices'!Q3:Q1006,"*Active*") -> 0
A27: Chandigarh | B27: =COUNTIF('📋 All Notices'!B3:B1006,"*Chandigarh*") -> 0 | C27: =SUMIF('📋 All Notices'!B3:B1006,"*Chandigarh*",'📋 All Notices'!I3:I1006) -> 0 | D27: =SUMIF('📋 All Notices'!B3:B1006,"*Chandigarh*",'📋 All Notices'!J3:J1006) -> 0 | E27: =SUMIF('📋 All Notices'!B3:B1006,"*Chandigarh*",'📋 All Notices'!K3:K1006) -> 0 | F27: =C27+D27+E27 -> 0 | G27: =SUMIF('📋 All Notices'!B3:B1006,"*Chandigarh*",'📋 All Notices'!L3:L1006) -> 0 | H27: =SUMIF('📋 All Notices'!B3:B1006,"*Chandigarh*",'📋 All Notices'!M3:M1006) -> 0 | I27: =SUMIF('📋 All Notices'!B3:B1006,"*Chandigarh*",'📋 All Notices'!N3:N1006) -> 0 | J27: =SUMIF('📋 All Notices'!B3:B1006,"*Chandigarh*",'📋 All Notices'!O3:O1006) -> 0 | K27: =SUMIF('📋 All Notices'!B3:B1006,"*Chandigarh*",'📋 All Notices'!P3:P1006) -> 0 | L27: =COUNTIFS('📋 All Notices'!B3:B1006,"*Chandigarh*",'📋 All Notices'!Q3:Q1006,"*Active*") -> 0
A28: Delhi | B28: =COUNTIF('📋 All Notices'!B3:B1006,"*Delhi*") -> 6 | C28: =SUMIF('📋 All Notices'!B3:B1006,"*Delhi*",'📋 All Notices'!I3:I1006) -> 9270096 | D28: =SUMIF('📋 All Notices'!B3:B1006,"*Delhi*",'📋 All Notices'!J3:J1006) -> 45121552 | E28: =SUMIF('📋 All Notices'!B3:B1006,"*Delhi*",'📋 All Notices'!K3:K1006) -> 45121552 | F28: =C28+D28+E28 -> 99513200 | G28: =SUMIF('📋 All Notices'!B3:B1006,"*Delhi*",'📋 All Notices'!L3:L1006) -> 26853961 | H28: =SUMIF('📋 All Notices'!B3:B1006,"*Delhi*",'📋 All Notices'!M3:M1006) -> 76618377 | I28: =SUMIF('📋 All Notices'!B3:B1006,"*Delhi*",'📋 All Notices'!N3:N1006) -> 0 | J28: =SUMIF('📋 All Notices'!B3:B1006,"*Delhi*",'📋 All Notices'!O3:O1006) -> 202985538 | K28: =SUMIF('📋 All Notices'!B3:B1006,"*Delhi*",'📋 All Notices'!P3:P1006) -> 512452 | L28: =COUNTIFS('📋 All Notices'!B3:B1006,"*Delhi*",'📋 All Notices'!Q3:Q1006,"*Active*") -> 5
A29: Haryana | B29: =COUNTIF('📋 All Notices'!B3:B1006,"*Haryana*") -> 11 | C29: =SUMIF('📋 All Notices'!B3:B1006,"*Haryana*",'📋 All Notices'!I3:I1006) -> 80551896 | D29: =SUMIF('📋 All Notices'!B3:B1006,"*Haryana*",'📋 All Notices'!J3:J1006) -> 23745519 | E29: =SUMIF('📋 All Notices'!B3:B1006,"*Haryana*",'📋 All Notices'!K3:K1006) -> 23745398 | F29: =C29+D29+E29 -> 128042813 | G29: =SUMIF('📋 All Notices'!B3:B1006,"*Haryana*",'📋 All Notices'!L3:L1006) -> 67863371 | H29: =SUMIF('📋 All Notices'!B3:B1006,"*Haryana*",'📋 All Notices'!M3:M1006) -> 91495150 | I29: =SUMIF('📋 All Notices'!B3:B1006,"*Haryana*",'📋 All Notices'!N3:N1006) -> 1652240 | J29: =SUMIF('📋 All Notices'!B3:B1006,"*Haryana*",'📋 All Notices'!O3:O1006) -> 2.8905357e+08 | K29: =SUMIF('📋 All Notices'!B3:B1006,"*Haryana*",'📋 All Notices'!P3:P1006) -> 4568357 | L29: =COUNTIFS('📋 All Notices'!B3:B1006,"*Haryana*",'📋 All Notices'!Q3:Q1006,"*Active*") -> 10
A30: Himachal Pradesh | B30: =COUNTIF('📋 All Notices'!B3:B1006,"*Himachal Pradesh*") -> 1 | C30: =SUMIF('📋 All Notices'!B3:B1006,"*Himachal Pradesh*",'📋 All Notices'!I3:I1006) -> 0 | D30: =SUMIF('📋 All Notices'!B3:B1006,"*Himachal Pradesh*",'📋 All Notices'!J3:J1006) -> 50299 | E30: =SUMIF('📋 All Notices'!B3:B1006,"*Himachal Pradesh*",'📋 All Notices'!K3:K1006) -> 50299 | F30: =C30+D30+E30 -> 100598 | G30: =SUMIF('📋 All Notices'!B3:B1006,"*Himachal Pradesh*",'📋 All Notices'!L3:L1006) -> 10562 | H30: =SUMIF('📋 All Notices'!B3:B1006,"*Himachal Pradesh*",'📋 All Notices'!M3:M1006) -> 10060 | I30: =SUMIF('📋 All Notices'!B3:B1006,"*Himachal Pradesh*",'📋 All Notices'!N3:N1006) -> 0 | J30: =SUMIF('📋 All Notices'!B3:B1006,"*Himachal Pradesh*",'📋 All Notices'!O3:O1006) -> 121220 | K30: =SUMIF('📋 All Notices'!B3:B1006,"*Himachal Pradesh*",'📋 All Notices'!P3:P1006) -> 10060 | L30: =COUNTIFS('📋 All Notices'!B3:B1006,"*Himachal Pradesh*",'📋 All Notices'!Q3:Q1006,"*Active*") -> 1
A31: Jharkhand | B31: =COUNTIF('📋 All Notices'!B3:B1006,"*Jharkhand*") -> 1 | C31: =SUMIF('📋 All Notices'!B3:B1006,"*Jharkhand*",'📋 All Notices'!I3:I1006) -> 0 | D31: =SUMIF('📋 All Notices'!B3:B1006,"*Jharkhand*",'📋 All Notices'!J3:J1006) -> 2454 | E31: =SUMIF('📋 All Notices'!B3:B1006,"*Jharkhand*",'📋 All Notices'!K3:K1006) -> 2454 | F31: =C31+D31+E31 -> 4908 | G31: =SUMIF('📋 All Notices'!B3:B1006,"*Jharkhand*",'📋 All Notices'!L3:L1006) -> 0 | H31: =SUMIF('📋 All Notices'!B3:B1006,"*Jharkhand*",'📋 All Notices'!M3:M1006) -> 4908 | I31: =SUMIF('📋 All Notices'!B3:B1006,"*Jharkhand*",'📋 All Notices'!N3:N1006) -> 0 | J31: =SUMIF('📋 All Notices'!B3:B1006,"*Jharkhand*",'📋 All Notices'!O3:O1006) -> 9816 | K31: =SUMIF('📋 All Notices'!B3:B1006,"*Jharkhand*",'📋 All Notices'!P3:P1006) -> 0 | L31: =COUNTIFS('📋 All Notices'!B3:B1006,"*Jharkhand*",'📋 All Notices'!Q3:Q1006,"*Active*") -> 1
A32: Karnataka | B32: =COUNTIF('📋 All Notices'!B3:B1006,"*Karnataka*") -> 1 | C32: =SUMIF('📋 All Notices'!B3:B1006,"*Karnataka*",'📋 All Notices'!I3:I1006) -> 0 | D32: =SUMIF('📋 All Notices'!B3:B1006,"*Karnataka*",'📋 All Notices'!J3:J1006) -> 66023 | E32: =SUMIF('📋 All Notices'!B3:B1006,"*Karnataka*",'📋 All Notices'!K3:K1006) -> 66023 | F32: =C32+D32+E32 -> 132046 | G32: =SUMIF('📋 All Notices'!B3:B1006,"*Karnataka*",'📋 All Notices'!L3:L1006) -> 0 | H32: =SUMIF('📋 All Notices'!B3:B1006,"*Karnataka*",'📋 All Notices'!M3:M1006) -> 132046 | I32: =SUMIF('📋 All Notices'!B3:B1006,"*Karnataka*",'📋 All Notices'!N3:N1006) -> 0 | J32: =SUMIF('📋 All Notices'!B3:B1006,"*Karnataka*",'📋 All Notices'!O3:O1006) -> 264092 | K32: =SUMIF('📋 All Notices'!B3:B1006,"*Karnataka*",'📋 All Notices'!P3:P1006) -> 0 | L32: =COUNTIFS('📋 All Notices'!B3:B1006,"*Karnataka*",'📋 All Notices'!Q3:Q1006,"*Active*") -> 1
A33: Kerala | B33: =COUNTIF('📋 All Notices'!B3:B1006,"*Kerala*") -> 1 | C33: =SUMIF('📋 All Notices'!B3:B1006,"*Kerala*",'📋 All Notices'!I3:I1006) -> 11351 | D33: =SUMIF('📋 All Notices'!B3:B1006,"*Kerala*",'📋 All Notices'!J3:J1006) -> 0 | E33: =SUMIF('📋 All Notices'!B3:B1006,"*Kerala*",'📋 All Notices'!K3:K1006) -> 0 | F33: =C33+D33+E33 -> 11351 | G33: =SUMIF('📋 All Notices'!B3:B1006,"*Kerala*",'📋 All Notices'!L3:L1006) -> 0 | H33: =SUMIF('📋 All Notices'!B3:B1006,"*Kerala*",'📋 All Notices'!M3:M1006) -> 11351 | I33: =SUMIF('📋 All Notices'!B3:B1006,"*Kerala*",'📋 All Notices'!N3:N1006) -> 0 | J33: =SUMIF('📋 All Notices'!B3:B1006,"*Kerala*",'📋 All Notices'!O3:O1006) -> 22702 | K33: =SUMIF('📋 All Notices'!B3:B1006,"*Kerala*",'📋 All Notices'!P3:P1006) -> 0 | L33: =COUNTIFS('📋 All Notices'!B3:B1006,"*Kerala*",'📋 All Notices'!Q3:Q1006,"*Active*") -> 1
A34: Maharashtra | B34: =COUNTIF('📋 All Notices'!B3:B1006,"*Maharashtra*") -> 3 | C34: =SUMIF('📋 All Notices'!B3:B1006,"*Maharashtra*",'📋 All Notices'!I3:I1006) -> 12421593 | D34: =SUMIF('📋 All Notices'!B3:B1006,"*Maharashtra*",'📋 All Notices'!J3:J1006) -> 2553241 | E34: =SUMIF('📋 All Notices'!B3:B1006,"*Maharashtra*",'📋 All Notices'!K3:K1006) -> 2553241 | F34: =C34+D34+E34 -> 17528075 | G34: =SUMIF('📋 All Notices'!B3:B1006,"*Maharashtra*",'📋 All Notices'!L3:L1006) -> 4406352 | H34: =SUMIF('📋 All Notices'!B3:B1006,"*Maharashtra*",'📋 All Notices'!M3:M1006) -> 12692975 | I34: =SUMIF('📋 All Notices'!B3:B1006,"*Maharashtra*",'📋 All Notices'!N3:N1006) -> 0 | J34: =SUMIF('📋 All Notices'!B3:B1006,"*Maharashtra*",'📋 All Notices'!O3:O1006) -> 34627402 | K34: =SUMIF('📋 All Notices'!B3:B1006,"*Maharashtra*",'📋 All Notices'!P3:P1006) -> 407998 | L34: =COUNTIFS('📋 All Notices'!B3:B1006,"*Maharashtra*",'📋 All Notices'!Q3:Q1006,"*Active*") -> 2
A35: Odisha | B35: =COUNTIF('📋 All Notices'!B3:B1006,"*Odisha*") -> 0 | C35: =SUMIF('📋 All Notices'!B3:B1006,"*Odisha*",'📋 All Notices'!I3:I1006) -> 0 | D35: =SUMIF('📋 All Notices'!B3:B1006,"*Odisha*",'📋 All Notices'!J3:J1006) -> 0 | E35: =SUMIF('📋 All Notices'!B3:B1006,"*Odisha*",'📋 All Notices'!K3:K1006) -> 0 | F35: =C35+D35+E35 -> 0 | G35: =SUMIF('📋 All Notices'!B3:B1006,"*Odisha*",'📋 All Notices'!L3:L1006) -> 0 | H35: =SUMIF('📋 All Notices'!B3:B1006,"*Odisha*",'📋 All Notices'!M3:M1006) -> 0 | I35: =SUMIF('📋 All Notices'!B3:B1006,"*Odisha*",'📋 All Notices'!N3:N1006) -> 0 | J35: =SUMIF('📋 All Notices'!B3:B1006,"*Odisha*",'📋 All Notices'!O3:O1006) -> 0 | K35: =SUMIF('📋 All Notices'!B3:B1006,"*Odisha*",'📋 All Notices'!P3:P1006) -> 0 | L35: =COUNTIFS('📋 All Notices'!B3:B1006,"*Odisha*",'📋 All Notices'!Q3:Q1006,"*Active*") -> 0
A36: Punjab | B36: =COUNTIF('📋 All Notices'!B3:B1006,"*Punjab*") -> 0 | C36: =SUMIF('📋 All Notices'!B3:B1006,"*Punjab*",'📋 All Notices'!I3:I1006) -> 0 | D36: =SUMIF('📋 All Notices'!B3:B1006,"*Punjab*",'📋 All Notices'!J3:J1006) -> 0 | E36: =SUMIF('📋 All Notices'!B3:B1006,"*Punjab*",'📋 All Notices'!K3:K1006) -> 0 | F36: =C36+D36+E36 -> 0 | G36: =SUMIF('📋 All Notices'!B3:B1006,"*Punjab*",'📋 All Notices'!L3:L1006) -> 0 | H36: =SUMIF('📋 All Notices'!B3:B1006,"*Punjab*",'📋 All Notices'!M3:M1006) -> 0 | I36: =SUMIF('📋 All Notices'!B3:B1006,"*Punjab*",'📋 All Notices'!N3:N1006) -> 0 | J36: =SUMIF('📋 All Notices'!B3:B1006,"*Punjab*",'📋 All Notices'!O3:O1006) -> 0 | K36: =SUMIF('📋 All Notices'!B3:B1006,"*Punjab*",'📋 All Notices'!P3:P1006) -> 0 | L36: =COUNTIFS('📋 All Notices'!B3:B1006,"*Punjab*",'📋 All Notices'!Q3:Q1006,"*Active*") -> 0
A37: Rajasthan | B37: =COUNTIF('📋 All Notices'!B3:B1006,"*Rajasthan*") -> 1 | C37: =SUMIF('📋 All Notices'!B3:B1006,"*Rajasthan*",'📋 All Notices'!I3:I1006) -> 0 | D37: =SUMIF('📋 All Notices'!B3:B1006,"*Rajasthan*",'📋 All Notices'!J3:J1006) -> 136515 | E37: =SUMIF('📋 All Notices'!B3:B1006,"*Rajasthan*",'📋 All Notices'!K3:K1006) -> 136515 | F37: =C37+D37+E37 -> 273030 | G37: =SUMIF('📋 All Notices'!B3:B1006,"*Rajasthan*",'📋 All Notices'!L3:L1006) -> 0 | H37: =SUMIF('📋 All Notices'!B3:B1006,"*Rajasthan*",'📋 All Notices'!M3:M1006) -> 273030 | I37: =SUMIF('📋 All Notices'!B3:B1006,"*Rajasthan*",'📋 All Notices'!N3:N1006) -> 0 | J37: =SUMIF('📋 All Notices'!B3:B1006,"*Rajasthan*",'📋 All Notices'!O3:O1006) -> 546060 | K37: =SUMIF('📋 All Notices'!B3:B1006,"*Rajasthan*",'📋 All Notices'!P3:P1006) -> 0 | L37: =COUNTIFS('📋 All Notices'!B3:B1006,"*Rajasthan*",'📋 All Notices'!Q3:Q1006,"*Active*") -> 1
A38: Tamil Nadu | B38: =COUNTIF('📋 All Notices'!B3:B1006,"*Tamil Nadu*") -> 0 | C38: =SUMIF('📋 All Notices'!B3:B1006,"*Tamil Nadu*",'📋 All Notices'!I3:I1006) -> 0 | D38: =SUMIF('📋 All Notices'!B3:B1006,"*Tamil Nadu*",'📋 All Notices'!J3:J1006) -> 0 | E38: =SUMIF('📋 All Notices'!B3:B1006,"*Tamil Nadu*",'📋 All Notices'!K3:K1006) -> 0 | F38: =C38+D38+E38 -> 0 | G38: =SUMIF('📋 All Notices'!B3:B1006,"*Tamil Nadu*",'📋 All Notices'!L3:L1006) -> 0 | H38: =SUMIF('📋 All Notices'!B3:B1006,"*Tamil Nadu*",'📋 All Notices'!M3:M1006) -> 0 | I38: =SUMIF('📋 All Notices'!B3:B1006,"*Tamil Nadu*",'📋 All Notices'!N3:N1006) -> 0 | J38: =SUMIF('📋 All Notices'!B3:B1006,"*Tamil Nadu*",'📋 All Notices'!O3:O1006) -> 0 | K38: =SUMIF('📋 All Notices'!B3:B1006,"*Tamil Nadu*",'📋 All Notices'!P3:P1006) -> 0 | L38: =COUNTIFS('📋 All Notices'!B3:B1006,"*Tamil Nadu*",'📋 All Notices'!Q3:Q1006,"*Active*") -> 0
A39: Telangana | B39: =COUNTIF('📋 All Notices'!B3:B1006,"*Telangana*") -> 2 | C39: =SUMIF('📋 All Notices'!B3:B1006,"*Telangana*",'📋 All Notices'!I3:I1006) -> 2899606 | D39: =SUMIF('📋 All Notices'!B3:B1006,"*Telangana*",'📋 All Notices'!J3:J1006) -> 2468045 | E39: =SUMIF('📋 All Notices'!B3:B1006,"*Telangana*",'📋 All Notices'!K3:K1006) -> 2468045 | F39: =C39+D39+E39 -> 7835696 | G39: =SUMIF('📋 All Notices'!B3:B1006,"*Telangana*",'📋 All Notices'!L3:L1006) -> 0 | H39: =SUMIF('📋 All Notices'!B3:B1006,"*Telangana*",'📋 All Notices'!M3:M1006) -> 699718 | I39: =SUMIF('📋 All Notices'!B3:B1006,"*Telangana*",'📋 All Notices'!N3:N1006) -> 0 | J39: =SUMIF('📋 All Notices'!B3:B1006,"*Telangana*",'📋 All Notices'!O3:O1006) -> 8535414 | K39: =SUMIF('📋 All Notices'!B3:B1006,"*Telangana*",'📋 All Notices'!P3:P1006) -> 0 | L39: =COUNTIFS('📋 All Notices'!B3:B1006,"*Telangana*",'📋 All Notices'!Q3:Q1006,"*Active*") -> 2
A40: Uttar Pradesh | B40: =COUNTIF('📋 All Notices'!B3:B1006,"*Uttar Pradesh*") -> 2 | C40: =SUMIF('📋 All Notices'!B3:B1006,"*Uttar Pradesh*",'📋 All Notices'!I3:I1006) -> 13504614 | D40: =SUMIF('📋 All Notices'!B3:B1006,"*Uttar Pradesh*",'📋 All Notices'!J3:J1006) -> 5319352 | E40: =SUMIF('📋 All Notices'!B3:B1006,"*Uttar Pradesh*",'📋 All Notices'!K3:K1006) -> 5319352 | F40: =C40+D40+E40 -> 24143318 | G40: =SUMIF('📋 All Notices'!B3:B1006,"*Uttar Pradesh*",'📋 All Notices'!L3:L1006) -> 0 | H40: =SUMIF('📋 All Notices'!B3:B1006,"*Uttar Pradesh*",'📋 All Notices'!M3:M1006) -> 24143318 | I40: =SUMIF('📋 All Notices'!B3:B1006,"*Uttar Pradesh*",'📋 All Notices'!N3:N1006) -> 0 | J40: =SUMIF('📋 All Notices'!B3:B1006,"*Uttar Pradesh*",'📋 All Notices'!O3:O1006) -> 48286636 | K40: =SUMIF('📋 All Notices'!B3:B1006,"*Uttar Pradesh*",'📋 All Notices'!P3:P1006) -> 0 | L40: =COUNTIFS('📋 All Notices'!B3:B1006,"*Uttar Pradesh*",'📋 All Notices'!Q3:Q1006,"*Active*") -> 2
