Workbook

Sheet Liquidation Tax Model
B1: BRIGHT AUTOCOMP PRIVATE LIMITED — Liquidation Tax Model
B2: CIN U35122HR2007PTC037071 · based on audited financials FY2024-25 · all amounts in actual Rupees (financials were in Rs.'00). Planning model, not tax advice.
B4: A. EXTRACTED FROM FINANCIALS (31 March 2025)
B5: Paid-up equity share capital (10,000 x Rs.10) | C5: 100000
B6: Reserve & Surplus = accumulated profits | C6: 5189668 | F6: Deemed-dividend base u/s 2(22)(c)
B7: Land & Building — book value / WDV | C7: 14574847 | F7: IMT Manesar plot · 0% depreciation · likely worth MUCH more at market
B8: Other assets (FD + receivables + cash) | C8: 6478085
B9: Total external liabilities (incl. Rs.1.54 cr related-party loan) | C9: 15763264 | F9: Must be repaid before any distribution to shareholders
B10: Net assets at book (= shareholders' funds) | C10: =C5+C6 | F10: Book value distributable if assets fetch only book value
B12: B. ASSUMPTIONS — edit the yellow cells
B13: Land & Building — MARKET VALUE (FMV) on sale | C13: 14574847 | F13: ** KEY INPUT ** default = book. Enter the real Manesar market value.
B14: Cost of Land for capital-gains (indexed cost if opting) | C14: 14574847 | F14: Original cost; no indexation under the 12.5% regime
B15: Company LTCG rate % (post 23-Jul-2024 = 12.5) | C15: 12.5
B16: Company surcharge % (7 if income <=10cr, else 12) | C16: 12
B17: Health & education cess % | C17: 4
B18: Shareholders' marginal tax rate % (incl. cess) | C18: 31.2 | F18: Deemed dividend taxed at slab; 31.2 = 30%+cess. Use 35.88/39 if surcharge applies
B19: Cost of acquisition of shares (both shareholders) | C19: 100000 | F19: Subscribed at par, no bonus (Note 3.4)
B21: C. COMPANY-LEVEL TAX (on realising assets to raise cash)
B22: Capital gain on Land & Building = FMV - cost | C22: =MAX(0,C13-C14) | F22: Sec 45; nil if land sold only at book value
B23: Company LTCG tax = gain x rate x (1+surcharge) x (1+cess) | C23: =ROUND(C22*C15/100*(1+C16/100)*(1+C17/100),0) | F23: Payable by the company before distributing
B25: D. AMOUNT DISTRIBUTABLE TO SHAREHOLDERS
B26: Book profit on land sale (FMV - book) | C26: =MAX(0,C13-C7)
B27: Accumulated profits after sale (net of company tax) | C27: =C6+C26-C23 | F27: Reserves + realised gain - company tax
B28: Total distribution to shareholders | C28: =C5+C27 | F28: Return of capital + post-tax reserves
B30: E. SHAREHOLDER-LEVEL TAX
B31: Deemed dividend u/s 2(22)(c) = accumulated profits | C31: =C27 | F31: Taxed as dividend at slab in shareholders' hands
B32: Capital gains u/s 46(2) = distribution - dividend - cost | C32: =MAX(0,C28-C31-C19) | F32: Usually 0 — the gain flows through reserves as dividend
B33: Return of capital (tax-free) = min(cost, distribution-dividend) | C33: =MIN(C19,C28-C31) | F33: Your own money back — not taxed
B34: Tax on deemed dividend = dividend x marginal rate | C34: =ROUND(C31*C18/100,0)
B35: Tax on 46(2) capital gains @ 12.5%+cess | C35: =ROUND(C32*12.5/100*(1+C17/100),0)
B36: TOTAL shareholder tax (both shareholders) | C36: =C34+C35
B38: F. PER SHAREHOLDER (Bikram Singh Chadha 50% · Sonu Chadha 50%)
C39: Each (50%)
B40: Distribution received | C40: =C28/2
B41: of which deemed dividend | C41: =C31/2
B42: of which tax-free return of capital | C42: =C33/2
B43: Personal tax payable | C43: =(C34+C35)/2
B44: Net in hand after personal tax | C44: =C40-C43
B46: G. SUMMARY — total tax cost of liquidation
B47: Company-level tax | C47: =C23
...

Sheet Shareholder Tax
B1: Tax in the hands of SHAREHOLDERS on the amount they receive
B2: Everything a shareholder receives on liquidation falls into three buckets, each taxed differently. Driven by the FMV on the 'Liquidation Tax Model' sheet.
C4: Both (100%) | D4: Each partner (50%)
B5: TOTAL AMOUNT RECEIVED by shareholders | C5: ='Liquidation Tax Model'!C28 | D5: =C5/2
B7: Split into three tax buckets:
B8: ① Return of paid-up capital | C8: ='Liquidation Tax Model'!C33 | D8: =C8/2 | E8: TAX-FREE — your own money, recovered as cost of shares u/s 46(2)
B9: ② Deemed dividend u/s 2(22)(c) | C9: ='Liquidation Tax Model'!C31 | D9: =C9/2 | E9: Reserves / accumulated profits — TAXABLE at slab
B10: ③ Capital gains u/s 46(2) | C10: ='Liquidation Tax Model'!C32 | D10: =C10/2 | E10: Amount above (dividend + cost) — TAXABLE as LTCG 12.5%
B11: Check: buckets ①+②+③ = total received | C11: ='Liquidation Tax Model'!C33+'Liquidation Tax Model'!C31+'Liquidation Tax Model'!C32 | D11: =C11/2 | E11: Must equal the total amount received above
B13: Tax on each bucket:
B14: Tax on ① return of capital | C14: =0 | D14: =C14/2 | E14: Nil — not income
B15: Tax on ② deemed dividend (at marginal slab) | C15: ='Liquidation Tax Model'!C34 | D15: =C15/2 | E15: =dividend x shareholders' rate cell
B16: Tax on ③ capital gains 46(2) @ 12.5% + cess | C16: ='Liquidation Tax Model'!C35 | D16: =C16/2
B17: TOTAL TAX in shareholders' hands | C17: ='Liquidation Tax Model'!C34+'Liquidation Tax Model'!C35 | D17: =C17/2
B18: NET RETAINED after tax | C18: ='Liquidation Tax Model'!C28-'Liquidation Tax Model'!C34-'Liquidation Tax Model'!C35 | D18: =C18/2
B19: Effective tax rate on amount received | C19: =('Liquidation Tax Model'!C34+'Liquidation Tax Model'!C35)/'Liquidation Tax Model'!C28 | D19: =C19
B21: Bottom line on the CAPITAL a shareholder receives: the return of the Rs.1,00,000 paid-up capital (Rs.50,000 each) is TAX-FREE. What is taxed is the reserves (as deemed dividend at slab) and any surplus over cost (as capital gains). At book value there is no capital gain, so only the reserves are taxed.
B22: Raise the land FMV on the model sheet and bucket ② (deemed dividend) grows — that is where the tax is.
B23: TDS u/s 194 may be deducted by the company on the deemed dividend. Not tax advice.

Sheet Land FMV Scenarios
B1: Land & Building — Market-Value Sensitivity (capital-gains tax at each FMV)
B2: Edit the yellow market-value row — every column recalculates. Rates pull from the 'Liquidation Tax Model' sheet (assumptions section).
B4: Land & Building MARKET VALUE (FMV) — EDIT ► | C4: ='Liquidation Tax Model'!C7 | D4: 25000000 | E4: 50000000 | F4: 75000000 | G4: 100000000 | H4: 150000000
B5: Company capital gain on land (FMV − cost) | C5: =MAX(0,C4-'Liquidation Tax Model'!C14) | D5: =MAX(0,D4-'Liquidation Tax Model'!C14) | E5: =MAX(0,E4-'Liquidation Tax Model'!C14) | F5: =MAX(0,F4-'Liquidation Tax Model'!C14) | G5: =MAX(0,G4-'Liquidation Tax Model'!C14) | H5: =MAX(0,H4-'Liquidation Tax Model'!C14)
B6: Company LTCG tax (rate + surcharge + cess) | C6: =ROUND(C5*'Liquidation Tax Model'!C15/100*(1+'Liquidation Tax Model'!C16/100)*(1+'Liquidation Tax Model'!C17/100),0) | D6: =ROUND(D5*'Liquidation Tax Model'!C15/100*(1+'Liquidation Tax Model'!C16/100)*(1+'Liquidation Tax Model'!C17/100),0) | E6: =ROUND(E5*'Liquidation Tax Model'!C15/100*(1+'Liquidation Tax Model'!C16/100)*(1+'Liquidation Tax Model'!C17/100),0) | F6: =ROUND(F5*'Liquidation Tax Model'!C15/100*(1+'Liquidation Tax Model'!C16/100)*(1+'Liquidation Tax Model'!C17/100),0) | G6: =ROUND(G5*'Liquidation Tax Model'!C15/100*(1+'Liquidation Tax Model'!C16/100)*(1+'Liquidation Tax Model'!C17/100),0) | H6: =ROUND(H5*'Liquidation Tax Model'!C15/100*(1+'Liquidation Tax Model'!C16/100)*(1+'Liquidation Tax Model'!C17/100),0)
B7: Book profit added to reserves (FMV − book) | C7: =MAX(0,C4-'Liquidation Tax Model'!C7) | D7: =MAX(0,D4-'Liquidation Tax Model'!C7) | E7: =MAX(0,E4-'Liquidation Tax Model'!C7) | F7: =MAX(0,F4-'Liquidation Tax Model'!C7) | G7: =MAX(0,G4-'Liquidation Tax Model'!C7) | H7: =MAX(0,H4-'Liquidation Tax Model'!C7)
B8: Accumulated profits after sale (= deemed dividend) | C8: ='Liquidation Tax Model'!C6+C7-C6 | D8: ='Liquidation Tax Model'!C6+D7-D6 | E8: ='Liquidation Tax Model'!C6+E7-E6 | F8: ='Liquidation Tax Model'!C6+F7-F6 | G8: ='Liquidation Tax Model'!C6+G7-G6 | H8: ='Liquidation Tax Model'!C6+H7-H6
B9: Total distribution to shareholders | C9: ='Liquidation Tax Model'!C5+C8 | D9: ='Liquidation Tax Model'!C5+D8 | E9: ='Liquidation Tax Model'!C5+E8 | F9: ='Liquidation Tax Model'!C5+F8 | G9: ='Liquidation Tax Model'!C5+G8 | H9: ='Liquidation Tax Model'!C5+H8
B10: Shareholder tax on deemed dividend (slab) | C10: =ROUND(C8*'Liquidation Tax Model'!C18/100,0) | D10: =ROUND(D8*'Liquidation Tax Model'!C18/100,0) | E10: =ROUND(E8*'Liquidation Tax Model'!C18/100,0) | F10: =ROUND(F8*'Liquidation Tax Model'!C18/100,0) | G10: =ROUND(G8*'Liquidation Tax Model'!C18/100,0) | H10: =ROUND(H8*'Liquidation Tax Model'!C18/100,0)
B11: Capital gains u/s 46(2) | C11: =MAX(0,C9-C8-'Liquidation Tax Model'!C19) | D11: =MAX(0,D9-D8-'Liquidation Tax Model'!C19) | E11: =MAX(0,E9-E8-'Liquidation Tax Model'!C19) | F11: =MAX(0,F9-F8-'Liquidation Tax Model'!C19) | G11: =MAX(0,G9-G8-'Liquidation Tax Model'!C19) | H11: =MAX(0,H9-H8-'Liquidation Tax Model'!C19)
B12: TOTAL TAX (company + shareholders) | C12: =C6+C10 | D12: =D6+D10 | E12: =E6+E10 | F12: =F6+F10 | G12: =G6+G10 | H12: =H6+H10
B13: Net reaching shareholders after ALL tax | C13: =C9-C10 | D13: =D9-D10 | E13: =E9-E10 | F13: =F9-F10 | G13: =G9-G10 | H13: =H9-H10
B14: Total tax as % of amount realised | C14: =(C6+C10)/(C9+C6) | D14: =(D6+D10)/(D9+D6) | E14: =(E6+E10)/(E9+E6) | F14: =(F6+F10)/(F9+F6) | G14: =(G6+G10)/(G9+G6) | H14: =(H6+H10)/(H9+H6)
B16: How to use: type any market value into the yellow row and read the TOTAL TAX and NET columns.
B17: The company pays 12.5% LTCG (+surcharge +cess) on the land gain; the post-tax gain enlarges the reserves, so shareholders then pay slab tax on a bigger deemed dividend. That is why total tax climbs fast with the land value.
B18: Sec 46(2) capital gain stays ~nil because the only sum above reserves is the paid-up capital, which equals its cost. Return of that capital is tax-free.
B19: Change the rates (LTCG %, surcharge %, shareholder slab %) on the 'Liquidation Tax Model' sheet — every scenario updates.
